Workbook

Sheet 01 ДОСЬЕ
B1: NCPD ▚ NIGHT CITY POLICE DEPARTMENT ▚ УПРАВЛЕНИЕ BORDER SECURITY ▚ 2070
B2: ФОРМА NCPD-77/Б · ДЕЛО ОБЪЕКТА · ДОСТУП: ОГРАНИЧЕННЫЙ · КОПИРОВАНИЕ БЕЗ ШТАМПА НЕДОПУСТИМО
B3: Д О С Ь Е | F3: СТАТУС: | G3: АКТИВЕН
B4: ▍▎▍▎▎▍▍▎▍▎▎▍▍▎▎▍▎▍▍▎▎▍▎▍▌▎▍▎▌▍▎▎▍▎▍▌▎▍▎▎▍▎▍▎▎▍▎▍▎▎▍▎▎▌▎▍▍ | F4: ДЕЛО № | G4: NC-2070-
B6: ПОЗЫВНОЙ (HANDLE) | D6: ИМЯ / ФАМИЛИЯ | F6: ФОТО ОБЪЕКТА (вставить изображение)
B7: РОЛЬ / АРХЕТИП | C7: Законник (Lawman) — NCPD, в отставке | D7: РАНГ РОЛИ | E7: Ранг 4 (Backup: вызов 1d10 ≤ 4)
B8: ИГРОК | D8: ВОЗРАСТ / ДАТА РОЖДЕНИЯ
B9: РОДНОЙ ЯЗЫК (4 БЕСПЛ.) | C9: Английский (родной, 4 беспл.) + Streetslang | D9: КУЛЬТУРНЫЕ КОРНИ | E9: Северная Америка, Найт-Сити
B10: РАЙОН (LOCAL EXPERT) | C10: Хейвуд — боевые зоны | D10: СТИЛЬ ОДЕЖДЫ | E10: Кожаная куртка поверх брони, зеркальные очки (Nomad Leathers)
B11: РОСТ / ВЕС / СЛОЖЕНИЕ | D11: ХРОМ НА ВИДУ | E11: Видимого функционального хрома нет: на предплечье светится выцветшая татуировка-значок, остальное внутри
B12: ОСОБЫЕ ПРИМЕТЫ | C12: Сухая правая кисть — старая работа с холодом | D12: ГОЛОС / МАНЕРА | E12: Низкий, ровный, «голос протокола» — короткие фразы
B13: СВЯЗЬ / HOLOPHONE | C13: Agent (Standard): личный номер, отвечает всегда | D13: ЖИЛЬЁ / LIFESTYLE | E13: Грузовой контейнер в боевых зонах Хейвуда (аренда) · Kibble Lifestyle
B14: СТАТУС ОБЪЕКТА: АКТИВЕН · КОНТАКТ ЧЕРЕЗ ФИКСЕРА · ДЕЛО ВЕДЁТ GM
B16: Ⅰ · ЛИЧНОСТЬ И МОТИВАЦИЯ · БЛОК ПСИХОПРОФИЛЯ
B17: ЛИЧНОСТЬ (PERSONALITY) | C17: Старый коп с протоколом вместо сердца. Говорит тихо, смотрит в глаза и почти никогда не повышает голос.
B18: ЧТО ЦЕНИТ БОЛЬШЕ ВСЕГО | C18: Порядок. Не закон — порядок: чтобы человек мог спокойно дойти до дома по своей улице.
B19: КАК ОТНОСИТСЯ К ЛЮДЯМ | C19: Считает, что большинство людей не злые, а испуганные. Ошибается реже, чем боится.
B20: МОРАЛЬНЫЙ КОМПАС (ПО ЛАЙФПАТУ) | C20: 5 — ЖЁСТКИЙ: гнёт правила и закон ради результата. Лишнего не делает, но и не мучается выбором.
B21: ЦЕЛЬ ЖИЗНИ / ЗАЧЕМ ОН В ЭТОМ | C21: Закрыть дело о корпоративном складе, из-за которого его выкинули из управления, — и вернуть себе имя.
B22: ЧЕГО НИКОГДА НЕ СДЕЛАЕТ | C22: Не тронет ребёнка. Не сдаст того, кто ему доверился, — даже если это стоило ему значка.
B23: СЛАБОСТЬ / НА ЧЁМ ЕГО ВЗЯТЬ | C23: Старые связи: звонок «Джек, надо» — и он едет, даже если понимает, что это подстава.
B25: Ⅱ · СЛУЖБА · ROLE LIFEPATH (LAWMAN / NCPD — В ОТСТАВКЕ)
B26: ДОЛЖНОСТЬ В ПОДРАЗДЕЛЕНИИ | C26: Уголовный следователь
B27: ЮРИСДИКЦИЯ ПОДРАЗДЕЛЕНИЯ | C27: Боевые зоны
B28: КОРРУМПИРОВАННОСТЬ ПОДРАЗДЕЛЕНИЯ | C28: Честная, но суровая
B29: КТО ОХОТИТСЯ НА ПОДРАЗДЕЛЕНИЕ | C29: Организованная преступность
B30: ГЛАВНАЯ ЦЕЛЬ ПОДРАЗДЕЛЕНИЯ | C30: Организованная преступность
B31: ЗА ЧТО УШЁЛ СО СЛУЖБЫ / ЧТО СЛУЧИЛОСЬ (ЕГО ВЕРСИЯ) | C31: Вёл дело о поставках оружия в боевые зоны и докопался до корпоративного склада. Сверху приказали дело закрыть — он отказался и продолжил копать. Через месяц его попросили на выход: «по собственному желанию», с пенсией и без значка. Официальная версия — «выгорание».
B32: ЧТО ОН НА САМОМ ДЕЛЕ СКРЫВАЕТ О ТОМ ДЕЛЕ | C32: Что знает, чем именно торговал склад, и что в деле есть фамилия человека, который сейчас сидит в управлении. Доказательств нет — поэтому он молчит и до сих пор жив.
B33: КАКИЕ СВЯЗИ В УПРАВЛЕНИИ ОСТАЛИСЬ (ЗВОНИТЬ МОЖНО КОМУ) | C33: Сержант из архива — достаёт копии закрытых дел за бутылку. Медэксперт со старых времён — осмотрит тихо и не оставит следов в системе.
B34: ПОДПИСКИ И РЕГУЛЯРНЫЕ ТРАТЫ (TRAUMA TEAM, ЖИЛЬЁ, ДОЛГИ) | C34: Наличных на старте нет — вышел из управления с нулём, всё до последнего евродоллара ушло в снаряжение. Жильё — контейнер в боевых зонах: жильё 1 000 €$ + Kibble 100 €$/мес = 1 100 €$ к 1-му числу каждого месяца (первый месяц покрыт). Подписок нет: Trauma Team Silver (500 €$/мес) не по карману — копит на разовый вызов с первых дел. Долгов нет, кредитная история убита вместе с карьерой.
B35: КТО НА НЕГО ОХОТИТСЯ (WHO'S GUNNING FOR YOU) | C35: Корпоративная служба безопасности того склада — и она умеет ждать. Второй в очереди — бустерганг «Ржавые Псы», которого он тогда не закрыл.
B36: РЕПУТАЦИЯ НА УЛИЦАХ / ЧЕМ ИЗВЕСТЕН | C36: В боевых зонах его знают как копа, который не брал процент и не сдавал своих.
B37: ТЕКУЩИЙ РАБОТОДАТЕЛЬ / ФИКСЕР | C37: Работает через фиксера средней руки (имя впиши сам — он ещё не назвался). Берёт и «левые» дела, если цель понятна.
B38: ПРАВИЛА РАБОТЫ (КАК БЕРЁТ КОНТРАКТЫ) | C38: Три вопроса перед делом: кто пострадает, кто платит, что будет, если он откажется.
B40: Ⅲ · ПРОШЛОЕ · GENERAL LIFEPATH
B41: СЕМЬЯ / ДЕТСТВО | C41: Вырос в боевых зонах Хейвуда: мать работала медсестрой в бесплатной клинике, отец ушёл в банду и не вернулся.
B42: СЕМЕЙНЫЙ КРИЗИС | C42: Мать погибла от шальной пули в перекрёстном огне — в тот год он и подал документы в академию NCPD.
B43: ДРУЗЬЯ | C43: Двое: сержант из архива, который всё ещё берёт трубку, и брат бывшего напарника, который его ненавидит.
B44: РОМАНТИЧЕСКИЕ СВЯЗИ | C44: Разведён. Жена не выдержала графика, ночных звонков и того, что он приносил работу домой.
...

Sheet 02 ОСНОВА
B1: ЛИСТ ПЕРСОНАЖА ▚ ОСНОВА ▚ CYBERPUNK RED / CEMK · НАЙТ-СИТИ, 2070-е
B2: ПОЗЫВНОЙ / РОЛЬ | E2: ='01 ДОСЬЕ'!C6&" · "&'01 ДОСЬЕ'!C7 | F2: РАНГ РОЛИ | G2: 4
B3: ИГРОК / СТАТУС ДЕЛА | E3: ='01 ДОСЬЕ'!C8&" · "&'01 ДОСЬЕ'!G3 | F3: СОСТОЯНИЕ РАН | G3: =IF(D25="","—",IF(D25<1,"СМЕРТЕЛЬНО РАНЕН",IF(D25<=D26,"СЕРЬЁЗНО РАНЕН",IF(D25<D24,"ЛЁГКОЕ РАНЕНИЕ","В НОРМЕ"))))
B4: КОНТАКТ / HOLOPHONE | E4: ='01 ДОСЬЕ'!C13 | F4: КИБЕРПСИХОЗ | G4: =IF(D36<0,"⚠ ПОРОГ ПРОЙДЕН",IF(D36<10,"⚠ НА ГРАНИ","—"))
B5: ЖЁЛТЫЕ ПОЛЯ — ВВОД · СЕРО-СИНИЕ — СЧИТАЕТСЯ АВТОМАТИЧЕСКИ · СТАТЫ ДАЮТ ИТОГ С УЧЁТОМ ШТРАФА БРОНИ (ЛИСТ 05)
B6: Ⅰ · ХАРАКТЕРИСТИКИ · 62 ОЧКА НА 10 СТАТ · КАЖДАЯ ОТ 2 ДО 8
B7: КОД | C7: СТАТА | D7: ЗНАЧ. | E7: БРОНЯ | F7: ИТОГ | G7: НА ЧТО ВЛИЯЕТ
B8: INT | C8: Интеллект | D8: 8 | E8: 0 | F8: =IF(D8="",0,MAX(0,D8-E8)) | G8: Ум, восприятие, обучение. База для Perception, Education, Local Expert
B9: WILL | C9: Воля | D9: 7 | E9: 0 | F9: =IF(D9="",0,MAX(0,D9-E9)) | G9: Решимость и стрессоустойчивость. Входит в расчёт HP. База для Concentr
B10: COOL | C10: Хладнокровие | D10: 7 | E10: 0 | F10: =IF(D10="",0,MAX(0,D10-E10)) | G10: Характер и харизма. База для Persuasion, Streetwise, Acting, Interroga
B11: EMP | C11: Эмпатия | D11: 5 | E11: 0 | F11: =IF(D11="",0,MIN(MAX(0,D11-E11),$D$37)) | G11: Сопереживание. База Humanity (EMP × 10) и EMP-навыков. Падает вместе с
B12: TECH | C12: Техника | D12: 3 | E12: 0 | F12: =IF(D12="",0,MAX(0,D12-E12)) | G12: Работа с инструментами и электроникой: Basic Tech, Cybertech, Weaponst
B13: REF | C13: Реакция | D13: 8 | E13: ='05 СНАРЯЖЕНИЕ'!$D$30 | F13: =IF(D13="",0,MAX(0,D13-E13)) | G13: Координация и прицеливание. Инициатива, все дальние атаки. Штраф брони
B14: LUCK | C14: Удача | D14: 2 | E14: 0 | F14: =IF(D14="",0,MAX(0,D14-E14)) | G14: Пул на любой бросок (до броска). Восстанавливается в начале следующей
B15: BODY | C15: Телосложение | D15: 8 | E15: 0 | F15: =IF(D15="",0,MAX(0,D15-E15)) | G15: Сила и живучесть. Входит в HP, задаёт спасбросок смерти. Штраф брони н
B16: DEX | C16: Ловкость | D16: 8 | E16: ='05 СНАРЯЖЕНИЕ'!$E$30 | F16: =IF(D16="",0,MAX(0,D16-E16)) | G16: Баланс, прыжки, ближний бой, уклонение. Штраф брони бьёт сюда.
B17: MOVE | C17: Скорость | D17: 6 | E17: ='05 СНАРЯЖЕНИЕ'!$F$30 | F17: =IF(D17="",0,MAX(0,D17-E17)) | G17: Перемещение: MOVE × 2 м за Move Action. Штраф брони бьёт сюда (может у
B18: РАСКИДАНО / НОРМА 62 | D18: =SUM(D8:D17) | E18: ОСТАТОК | F18: =62-SUM(D8:D17) | G18: =IF(F18=0,"✔ ровно 62 очка","свободно: "&F18&" (нужно раздать все 62)")
B19: ПРОВЕРКА | D19: =IF(AND(SUM(D8:D17)=62,MIN(D8:D17)>=2,MAX(D8:D17)<=8),"✔ 62 очка, диапазон 2–8 соблюдён","✖ ПРОВЕРЬ: сумма должна быть 62, каждая стата 2–8")
B20: Штраф брони вычитается из REF, DEX и MOVE — он берётся один раз, самый строгий из надетого (лист 05). Броня режет и навыки на этих статах автоматически (лист 03).
B22: Ⅱ · ПРОИЗВОДНЫЕ · HP, ЧЕЛОВЕЧНОСТЬ, ИНИЦИАТИВА
B23: ПОКАЗАТЕЛЬ | D23: ЗНАЧЕНИЕ | E23: ФОРМУЛА / ПРАВИЛО
B24: HP МАКСИМУМ | D24: =10+5*ROUNDUP((F15+F9)/2,0) | E24: HP = 10 + 5 × ⌈(BODY+WILL)/2⌉. Считается по ИТОГОВЫМ статам, но броня на них не влияет.
B25: HP ТЕКУЩИЕ (ВВОД) | D25: 50 | E25: Просто вписывай текущие HP. Ноль и ниже — смертельное состояние.
B26: ПОРОГ «СЕРЬЁЗНО РАНЕН» | D26: =ROUNDUP(D24/2,0) | E26: Половина максимума, округление вверх → −2 ко всем действиям.
B27: СПАСБРОСОК СМЕРТИ (BODY) | D27: =F15 | E27: 1d10 ≤ BODY − штраф. Выпало 10 — провал. Провал = смерть.
B28: ШТРАФ К СПАСБРОСКАМ (ВВОД) | D28: 0 | E28: Складывается с крит-травм (+1 за каждую такую травму) и урона.
B29: ИНИЦИАТИВА (REF + 1D10) | D29: =F13 | E29: Бросок 1d10 + это число. Combat Awareness: +1 за каждое вложенное очко в Initiative Reaction.
B30: MOVE ACTION (МЕТРЫ) | D30: =F17*2 | E30: За Move Action персонаж двигается на MOVE × 2 м. Ход = Move Action + одно действие.
B31: HUMANITY: БАЗА (EMP × 10) | D31: =D11*10 | E31: Считается от исходной EMP (колонка «ЗНАЧ.»), не от текущей.
B32: СРЕЗ МАКСИМУМА ЗА ХРОМ | D32: ='04 ХРОМ'!$I$25 | E32: −2 за каждый обычный имплант, −4 за боргвар, Fashionware не режет максимум (лист 04).
B33: HUMANITY МАКСИМУМ | D33: =D31-D32 | E33: Максимум Humanity = база − срез. Полностью вернуть можно только сняв хром.
B34: HL ВСЕГО (СРЕДНЕЕ) | D34: ='04 ХРОМ'!$H$25 | E34: Среднее значение HL каждого установленного импланта (дом-правило кампании: «7 (2d6)» = −7).
B35: ВОССТАНОВЛЕНО (ТЕРАПИЯ/ОПЫТ) | E35: Сколько Humanity вернули терапией, опытом или событиями кампании (CEMK: Humanity Gain).
B36: HUMANITY ТЕКУЩАЯ | D36: =MIN(D33,D31-D34+D35) | E36: Не может превышать максимум. Ниже 0 — киберпсихоз, лист уходит GM.
B37: EMP ТЕКУЩАЯ | D37: =MAX(0,ROUNDDOWN(D36/10,0)) | E37: Каждый раз, когда десяток Humanity падает, падает и EMP.
B38: СТАТУС HUMANITY | D38: =IF(D36<0,"⚠ КИБЕРПСИХОЗ",IF(D36<10,"⚠ НА ГРАНИ",IF(D36<20,"ПОНИЖЕННАЯ","В НОРМЕ"))) | E38: Порог киберпсихоза: 0 Humanity. EMP 0 = отстранённость, диссоциация, «люди — детали».
B40: Ⅲ · РОЛЕВАЯ СПОСОБНОСТЬ · A: SOLO — COMBAT AWARENESS · B: LAWMAN — BACKUP
B41: СПОСОБНОСТЬ | C41: ЦЕНА ЗА ЭФФЕКТ | D41: ВЛОЖЕНО ОЧКОВ | E41: ЧТО ЭТО ДАЁТ
B42: Damage Deflection | C42: 2 очка за −1 урона | D42: 0 | E42: Уменьшает первый урон раунда: 2/4/6/8/10 очков = −1…−5.
...

Sheet 03 НАВЫКИ
B1: НАВЫКИ ▚ 86 ОЧКОВ ▚ МАКСИМУМ 6 ПРИ СОЗДАНИИ ▚ МИН. 2 В 13 ОБЯЗАТЕЛЬНЫХ
B2: РАБОЧАЯ ТАБЛИЦА НАВЫКОВ · ЗАПОЛНЯЙ ТОЛЬКО СТОЛБЕЦ «УР.» | F2: РАСКИДАНО | G2: =SUM($J$5:$J$76) | H2: ОСТАТОК | I2: =86-$G$2 | J2: =IF($I$2=0,"✔ 86 очков распределены полностью",IF($I$2>0,"свободно: "&$I$2&" очков","✖ перебор на "&-$I$2&" очков"))
B3: ★ — обязательный пакет роли LAWMAN (мин. 2 каждому): Autofire (×2), Criminology, Deduction, Handgun, Interrogation, Shoulder Arms, Tracking. ☆ — пакет Solo на случай смены роли. 13 обязательных для всех: Athletics, Brawling, Concentration, Conversation, Education, Evasion, First Aid, Human Perception, Language (Streetslang), Local Expert (твой район), Perception, Persuasion, Stealth. Навыки с ×2 стоят 2 очка за уровень.
B4: ГРУППА | C4: НАВЫК | D4: СТАТА | E4: ×2 | F4: РОЛЬ | G4: УР. | H4: СТАТА | I4: БАЗА | J4: ОЧКИ | K4: СПЕЦИАЛИЗАЦИЯ | L4: ЧТО ЭТО / ЗАМЕТКА
B5: Осознание | C5: Concentration | D5: WILL | F5: ☆ | G5: 2 | H5: =IFERROR(INDEX('02 ОСНОВА'!$F$8:$F$17,MATCH($D5,'02 ОСНОВА'!$B$8:$B$17,0)),"") | I5: =IF($G5="","",$G5+IFERROR($H5,0)) | J5: =IF($G5="",0,IF($E5="×2",$G5*2,$G5)) | L5: ОБЯЗАТЕЛЬНЫЙ: минимум 2. Фокусировка и ментальный контроль, память, игнорирование отвлекающих факторов.
B6: Осознание | C6: Conceal/Reveal Object | D6: INT | H6: =IFERROR(INDEX('02 ОСНОВА'!$F$8:$F$17,MATCH($D6,'02 ОСНОВА'!$B$8:$B$17,0)),"") | I6: =IF($G6="","",$G6+IFERROR($H6,0)) | J6: =IF($G6="",0,IF($E6="×2",$G6*2,$G6)) | L6: Скрытие и поиск спрятанных объектов. Прятать оружие под одеждой и выявлять его.
B7: Осознание | C7: Lip Reading | D7: INT | H7: =IFERROR(INDEX('02 ОСНОВА'!$F$8:$F$17,MATCH($D7,'02 ОСНОВА'!$B$8:$B$17,0)),"") | I7: =IF($G7="","",$G7+IFERROR($H7,0)) | J7: =IF($G7="",0,IF($E7="×2",$G7*2,$G7)) | L7: Чтение по губам.
B8: Осознание | C8: Perception | D8: INT | F8: ☆ | G8: 6 | H8: =IFERROR(INDEX('02 ОСНОВА'!$F$8:$F$17,MATCH($D8,'02 ОСНОВА'!$B$8:$B$17,0)),"") | I8: =IF($G8="","",$G8+IFERROR($H8,0)) | J8: =IF($G8="",0,IF($E8="×2",$G8*2,$G8)) | L8: ОБЯЗАТЕЛЬНЫЙ: минимум 2. Обнаружение скрытого: улики, ловушки, крадущиеся (но не спрятанное Conceal/Reveal Object).
B9: Осознание | C9: Tracking | D9: INT | F9: ★ | G9: 4 | H9: =IFERROR(INDEX('02 ОСНОВА'!$F$8:$F$17,MATCH($D9,'02 ОСНОВА'!$B$8:$B$17,0)),"") | I9: =IF($G9="","",$G9+IFERROR($H9,0)) | J9: =IF($G9="",0,IF($E9="×2",$G9*2,$G9)) | L9: Отслеживание по следам и уликам.
B10: Тело | C10: Athletics | D10: DEX | F10: ☆ | G10: 2 | H10: =IFERROR(INDEX('02 ОСНОВА'!$F$8:$F$17,MATCH($D10,'02 ОСНОВА'!$B$8:$B$17,0)),"") | I10: =IF($G10="","",$G10+IFERROR($H10,0)) | J10: =IF($G10="",0,IF($E10="×2",$G10*2,$G10)) | L10: ОБЯЗАТЕЛЬНЫЙ: минимум 2. Прыжки, карабкание, броски, лазание, плавание, подъём вещей.
B11: Тело | C11: Contortionist | D11: DEX | H11: =IFERROR(INDEX('02 ОСНОВА'!$F$8:$F$17,MATCH($D11,'02 ОСНОВА'!$B$8:$B$17,0)),"") | I11: =IF($G11="","",$G11+IFERROR($H11,0)) | J11: =IF($G11="",0,IF($E11="×2",$G11*2,$G11)) | L11: Выбраться из наручников, протискиваться в труднодоступные места.
B12: Тело | C12: Dance | D12: DEX | H12: =IFERROR(INDEX('02 ОСНОВА'!$F$8:$F$17,MATCH($D12,'02 ОСНОВА'!$B$8:$B$17,0)),"") | I12: =IF($G12="","",$G12+IFERROR($H12,0)) | J12: =IF($G12="",0,IF($E12="×2",$G12*2,$G12)) | L12: Профессиональные танцы.
B13: Тело | C13: Endurance | D13: WILL | H13: =IFERROR(INDEX('02 ОСНОВА'!$F$8:$F$17,MATCH($D13,'02 ОСНОВА'!$B$8:$B$17,0)),"") | I13: =IF($G13="","",$G13+IFERROR($H13,0)) | J13: =IF($G13="",0,IF($E13="×2",$G13*2,$G13)) | L13: Преодоление тяжёлых условий и тягот.
B14: Тело | C14: Resist Torture/Drugs | D14: WILL | F14: ☆ | H14: =IFERROR(INDEX('02 ОСНОВА'!$F$8:$F$17,MATCH($D14,'02 ОСНОВА'!$B$8:$B$17,0)),"") | I14: =IF($G14="","",$G14+IFERROR($H14,0)) | J14: =IF($G14="",0,IF($E14="×2",$G14*2,$G14)) | L14: Сопротивление допросу, пыткам и наркотикам.
B15: Тело | C15: Stealth | D15: DEX | F15: ☆ | G15: 2 | H15: =IFERROR(INDEX('02 ОСНОВА'!$F$8:$F$17,MATCH($D15,'02 ОСНОВА'!$B$8:$B$17,0)),"") | I15: =IF($G15="","",$G15+IFERROR($H15,0)) | J15: =IF($G15="",0,IF($E15="×2",$G15*2,$G15)) | L15: ОБЯЗАТЕЛЬНЫЙ: минимум 2. Тихое перемещение и скрытность. Против — Perception.
B16: Управление | C16: Drive Land Vehicle | D16: REF | H16: =IFERROR(INDEX('02 ОСНОВА'!$F$8:$F$17,MATCH($D16,'02 ОСНОВА'!$B$8:$B$17,0)),"") | I16: =IF($G16="","",$G16+IFERROR($H16,0)) | J16: =IF($G16="",0,IF($E16="×2",$G16*2,$G16)) | L16: Вождение наземного транспорта.
B17: Управление | C17: Pilot Air Vehicle | D17: REF | E17: ×2 | H17: =IFERROR(INDEX('02 ОСНОВА'!$F$8:$F$17,MATCH($D17,'02 ОСНОВА'!$B$8:$B$17,0)),"") | I17: =IF($G17="","",$G17+IFERROR($H17,0)) | J17: =IF($G17="",0,IF($E17="×2",$G17*2,$G17))
B18: Управление | C18: Pilot Sea Vehicle | D18: REF | H18: =IFERROR(INDEX('02 ОСНОВА'!$F$8:$F$17,MATCH($D18,'02 ОСНОВА'!$B$8:$B$17,0)),"") | I18: =IF($G18="","",$G18+IFERROR($H18,0)) | J18: =IF($G18="",0,IF($E18="×2",$G18*2,$G18)) | L18: Управление водным транспортом.
B19: Управление | C19: Riding | D19: REF | H19: =IFERROR(INDEX('02 ОСНОВА'!$F$8:$F$17,MATCH($D19,'02 ОСНОВА'!$B$8:$B$17,0)),"") | I19: =IF($G19="","",$G19+IFERROR($H19,0)) | J19: =IF($G19="",0,IF($E19="×2",$G19*2,$G19)) | L19: Верховая езда на обученном животном.
B20: Образование | C20: Accounting | D20: INT | H20: =IFERROR(INDEX('02 ОСНОВА'!$F$8:$F$17,MATCH($D20,'02 ОСНОВА'!$B$8:$B$17,0)),"") | I20: =IF($G20="","",$G20+IFERROR($H20,0)) | J20: =IF($G20="",0,IF($E20="×2",$G20*2,$G20)) | L20: Бухгалтерия: липовые отчёты и их выявление, бюджет, бизнес-операции.
B21: Образование | C21: Animal Handling | D21: INT | H21: =IFERROR(INDEX('02 ОСНОВА'!$F$8:$F$17,MATCH($D21,'02 ОСНОВА'!$B$8:$B$17,0)),"") | I21: =IF($G21="","",$G21+IFERROR($H21,0)) | J21: =IF($G21="",0,IF($E21="×2",$G21*2,$G21)) | L21: Обращение, дрессировка и уход за животными.
B22: Образование | C22: Bureaucracy | D22: INT | H22: =IFERROR(INDEX('02 ОСНОВА'!$F$8:$F$17,MATCH($D22,'02 ОСНОВА'!$B$8:$B$17,0)),"") | I22: =IF($G22="","",$G22+IFERROR($H22,0)) | J22: =IF($G22="",0,IF($E22="×2",$G22*2,$G22)) | L22: Работа с бюрократией: с кем говорить и как выбивать информацию.
B23: Образование | C23: Business | D23: INT | H23: =IFERROR(INDEX('02 ОСНОВА'!$F$8:$F$17,MATCH($D23,'02 ОСНОВА'!$B$8:$B$17,0)),"") | I23: =IF($G23="","",$G23+IFERROR($H23,0)) | J23: =IF($G23="",0,IF($E23="×2",$G23*2,$G23)) | L23: Бизнес-практики, спрос и предложение, закупки, продажи, маркетинг.
B24: Образование | C24: Composition | D24: INT | H24: =IFERROR(INDEX('02 ОСНОВА'!$F$8:$F$17,MATCH($D24,'02 ОСНОВА'!$B$8:$B$17,0)),"") | I24: =IF($G24="","",$G24+IFERROR($H24,0)) | J24: =IF($G24="",0,IF($E24="×2",$G24*2,$G24)) | L24: Профессиональное написание песен, статей, историй.
B25: Образование | C25: Criminology | D25: INT | F25: ★ | G25: 5 | H25: =IFERROR(INDEX('02 ОСНОВА'!$F$8:$F$17,MATCH($D25,'02 ОСНОВА'!$B$8:$B$17,0)),"") | I25: =IF($G25="","",$G25+IFERROR($H25,0)) | J25: =IF($G25="",0,IF($E25="×2",$G25*2,$G25)) | L25: Поиск улик: отпечатки, баллистика, полицейские базы.
B26: Образование | C26: Cryptography | D26: INT | H26: =IFERROR(INDEX('02 ОСНОВА'!$F$8:$F$17,MATCH($D26,'02 ОСНОВА'!$B$8:$B$17,0)),"") | I26: =IF($G26="","",$G26+IFERROR($H26,0)) | J26: =IF($G26="",0,IF($E26="×2",$G26*2,$G26)) | L26: Шифрование и расшифровка сообщений.
B27: Образование | C27: Deduction | D27: INT | F27: ★ | G27: 5 | H27: =IFERROR(INDEX('02 ОСНОВА'!$F$8:$F$17,MATCH($D27,'02 ОСНОВА'!$B$8:$B$17,0)),"") | I27: =IF($G27="","",$G27+IFERROR($H27,0)) | J27: =IF($G27="",0,IF($E27="×2",$G27*2,$G27)) | L27: Приходить к неочевидным выводам из улик (и мед. диагнозам).
B28: Образование | C28: Education | D28: INT | F28: ☆ | G28: 2 | H28: =IFERROR(INDEX('02 ОСНОВА'!$F$8:$F$17,MATCH($D28,'02 ОСНОВА'!$B$8:$B$17,0)),"") | I28: =IF($G28="","",$G28+IFERROR($H28,0)) | J28: =IF($G28="",0,IF($E28="×2",$G28*2,$G28)) | L28: ОБЯЗАТЕЛЬНЫЙ: минимум 2. Общая эрудиция: чтение, письмо, базовые вычисления, история.
B29: Образование | C29: Gamble | D29: INT | H29: =IFERROR(INDEX('02 ОСНОВА'!$F$8:$F$17,MATCH($D29,'02 ОСНОВА'!$B$8:$B$17,0)),"") | I29: =IF($G29="","",$G29+IFERROR($H29,0)) | J29: =IF($G29="",0,IF($E29="×2",$G29*2,$G29)) | L29: Вероятности и стратегия в азартных играх.
B30: Образование | C30: Language | D30: INT | F30: ☆ | G30: 2 | H30: =IFERROR(INDEX('02 ОСНОВА'!$F$8:$F$17,MATCH($D30,'02 ОСНОВА'!$B$8:$B$17,0)),"") | I30: =IF($G30="","",$G30+IFERROR($H30,0)) | J30: =IF($G30="",0,IF($E30="×2",$G30*2,$G30)) | K30: Streetslang | L30: ОБЯЗАТЕЛЬНЫЙ: минимум 2. Конкретный язык (выбирается при прокачке).
B31: Образование | C31: Library Search | D31: INT | H31: =IFERROR(INDEX('02 ОСНОВА'!$F$8:$F$17,MATCH($D31,'02 ОСНОВА'!$B$8:$B$17,0)),"") | I31: =IF($G31="","",$G31+IFERROR($H31,0)) | J31: =IF($G31="",0,IF($E31="×2",$G31*2,$G31)) | L31: Поиск по базам данных, Data Pool, библиотекам.
B32: Образование | C32: Local Expert | D32: INT | F32: ☆ | G32: 2 | H32: =IFERROR(INDEX('02 ОСНОВА'!$F$8:$F$17,MATCH($D32,'02 ОСНОВА'!$B$8:$B$17,0)),"") | I32: =IF($G32="","",$G32+IFERROR($H32,0)) | J32: =IF($G32="",0,IF($E32="×2",$G32*2,$G32)) | K32: Хейвуд | L32: ОБЯЗАТЕЛЬНЫЙ: минимум 2. Знание местности и целей группировок. Выберите район.
B33: Образование | C33: Science | D33: INT | H33: =IFERROR(INDEX('02 ОСНОВА'!$F$8:$F$17,MATCH($D33,'02 ОСНОВА'!$B$8:$B$17,0)),"") | I33: =IF($G33="","",$G33+IFERROR($H33,0)) | J33: =IF($G33="",0,IF($E33="×2",$G33*2,$G33)) | L33: Эксперименты, научные работы. Выберите область: геология, химия, биология…
B34: Образование | C34: Tactics | D34: INT | F34: ☆ | H34: =IFERROR(INDEX('02 ОСНОВА'!$F$8:$F$17,MATCH($D34,'02 ОСНОВА'!$B$8:$B$17,0)),"") | I34: =IF($G34="","",$G34+IFERROR($H34,0)) | J34: =IF($G34="",0,IF($E34="×2",$G34*2,$G34)) | L34: Руководство большими битвами: как поведут себя силы противника.
B35: Образование | C35: Wilderness Survival | D35: INT | H35: =IFERROR(INDEX('02 ОСНОВА'!$F$8:$F$17,MATCH($D35,'02 ОСНОВА'!$B$8:$B$17,0)),"") | I35: =IF($G35="","",$G35+IFERROR($H35,0)) | J35: =IF($G35="",0,IF($E35="×2",$G35*2,$G35)) | L35: Выживание в дикой природе.
B36: Бой | C36: Brawling | D36: DEX | F36: ☆ | G36: 5 | H36: =IFERROR(INDEX('02 ОСНОВА'!$F$8:$F$17,MATCH($D36,'02 ОСНОВА'!$B$8:$B$17,0)),"") | I36: =IF($G36="","",$G36+IFERROR($H36,0)) | J36: =IF($G36="",0,IF($E36="×2",$G36*2,$G36)) | L36: ОБЯЗАТЕЛЬНЫЙ: минимум 2. Уличные драки и захваты грубой силой.
B37: Бой | C37: Evasion | D37: DEX | F37: ☆ | G37: 6 | H37: =IFERROR(INDEX('02 ОСНОВА'!$F$8:$F$17,MATCH($D37,'02 ОСНОВА'!$B$8:$B$17,0)),"") | I37: =IF($G37="","",$G37+IFERROR($H37,0)) | J37: =IF($G37="",0,IF($E37="×2",$G37*2,$G37)) | L37: ОБЯЗАТЕЛЬНЫЙ: минимум 2. Уход с линии атаки. С REF 8+ — уклонение и от дальнего боя.
B38: Бой | C38: Martial Arts | D38: DEX | E38: ×2 | G38: 5 | H38: =IFERROR(INDEX('02 ОСНОВА'!$F$8:$F$17,MATCH($D38,'02 ОСНОВА'!$B$8:$B$17,0)),"") | I38: =IF($G38="","",$G38+IFERROR($H38,0)) | J38: =IF($G38="",0,IF($E38="×2",$G38*2,$G38)) | K38: Thamoc | L38: выбери вариант
B39: Бой | C39: Melee Weapon | D39: DEX | F39: ☆ | H39: =IFERROR(INDEX('02 ОСНОВА'!$F$8:$F$17,MATCH($D39,'02 ОСНОВА'!$B$8:$B$17,0)),"") | I39: =IF($G39="","",$G39+IFERROR($H39,0)) | J39: =IF($G39="",0,IF($E39="×2",$G39*2,$G39)) | L39: Орудование оружием ближнего боя.
B40: Выступление | C40: Acting | D40: COOL | H40: =IFERROR(INDEX('02 ОСНОВА'!$F$8:$F$17,MATCH($D40,'02 ОСНОВА'!$B$8:$B$17,0)),"") | I40: =IF($G40="","",$G40+IFERROR($H40,0)) | J40: =IF($G40="",0,IF($E40="×2",$G40*2,$G40)) | L40: Отыгрыш роли, маскировка под другого, изображение эмоций.
...

Sheet 04 ХРОМ
B1: КИБЕРНЕТИКА ▚ ЮГАС / ХРОМ ▚ 2070: ВЕСЬ НЕМЕДИЦИНСКИЙ ХРОМ ТРЕБУЕТ NEUROPORT
B2: HL СЧИТАЕТСЯ ПО СРЕДНЕМУ ЗНАЧЕНИЮ (7 (2D6) → 7) · СРЕЗ МАКСИМУМА: −2 ОБЫЧНЫЙ, −4 БОРГВАР | G2: HL: | H2: =$H$25 | I2: СРЕЗ: | J2: =$I$25 | K2: €$ В БЮДЖЕТ: | L2: =SUM($M$5:$M$24)+SUM($N$5:$N$24)
B3: Пиши название как в КАТАЛОГЕ — категория, цена, HL, срез и клиника подтянутся сами. Столбец «СЛОТ» — куда ставится: нейролинк, правый киберарм, опция 1 и т.п. В бюджет листа 05 попадают только отмеченные «Да» и только то, чего ещё нет в инвентаре: «В БЮДЖЕТ €$» — в стартовые 2550, «СТИЛЬ €$» — Fashionware в 800. Neuroport при создании: 0 €$ и 0 HL.
B4: № | C4: НАЗВАНИЕ (КАК В КАТАЛОГЕ) | D4: КАТЕГОРИЯ | E4: ПОДТИП | F4: СЛОТ / КУДА | G4: ЦЕНА €$ | H4: HL | I4: СРЕЗ | J4: УСТАНОВЛЕН | K4: КЛИНИКА | L4: ЭФФЕКТ / ЗАМЕТКА | M4: В БЮДЖЕТ €$ | N4: СТИЛЬ €$
B5: 1 | C5: Neuroport | D5: =IFERROR(INDEX('КАТАЛОГ'!$B$2:$B$1093,MATCH($C5,'КАТАЛОГ'!$A$2:$A$1093,0)),"") | E5: =IFERROR(INDEX('КАТАЛОГ'!$C$2:$C$1093,MATCH($C5,'КАТАЛОГ'!$A$2:$A$1093,0)),"") | G5: =IF($C5="",0,IF(ISNUMBER(SEARCH("Neuroport",$C5)),0,IFERROR(INDEX('КАТАЛОГ'!$R$2:$R$1093,MATCH($C5,'КАТАЛОГ'!$A$2:$A$1093,0)),0))) | H5: =IF($C5="",0,IF(ISNUMBER(SEARCH("Neuroport",$C5)),0,IFERROR(INDEX('КАТАЛОГ'!$M$2:$M$1093,MATCH($C5,'КАТАЛОГ'!$A$2:$A$1093,0)),0))) | I5: =IF($C5="",0,IF(OR(N($H5)=0,ISNUMBER(SEARCH("Fashionware",$E5))),0,IF(ISNUMBER(SEARCH("Borgware",$E5)),4,2))) | J5: Да | K5: =IFERROR(INDEX('КАТАЛОГ'!$N$2:$N$1093,MATCH($C5,'КАТАЛОГ'!$A$2:$A$1093,0)),"") | L5: Нейролинк, бесплатно в 2070-х | M5: =IF($C5="",0,IF($J5<>"Да",0,IF(ISNUMBER(SEARCH("Fashionware",$E5)),0,IF(COUNTIF('05 СНАРЯЖЕНИЕ'!$C$34:$C$53,$C5)>0,0,$G5)))) | N5: =IF($C5="",0,IF($J5<>"Да",0,IF(ISNUMBER(SEARCH("Fashionware",$E5)),$G5,0)))
B6: 2 | C6: Cyberaudio Suite | D6: =IFERROR(INDEX('КАТАЛОГ'!$B$2:$B$1093,MATCH($C6,'КАТАЛОГ'!$A$2:$A$1093,0)),"") | E6: =IFERROR(INDEX('КАТАЛОГ'!$C$2:$C$1093,MATCH($C6,'КАТАЛОГ'!$A$2:$A$1093,0)),"") | G6: =IF($C6="",0,IF(ISNUMBER(SEARCH("Neuroport",$C6)),0,IFERROR(INDEX('КАТАЛОГ'!$R$2:$R$1093,MATCH($C6,'КАТАЛОГ'!$A$2:$A$1093,0)),0))) | H6: =IF($C6="",0,IF(ISNUMBER(SEARCH("Neuroport",$C6)),0,IFERROR(INDEX('КАТАЛОГ'!$M$2:$M$1093,MATCH($C6,'КАТАЛОГ'!$A$2:$A$1093,0)),0))) | I6: =IF($C6="",0,IF(OR(N($H6)=0,ISNUMBER(SEARCH("Fashionware",$E6))),0,IF(ISNUMBER(SEARCH("Borgware",$E6)),4,2))) | J6: Да | K6: =IFERROR(INDEX('КАТАЛОГ'!$N$2:$N$1093,MATCH($C6,'КАТАЛОГ'!$A$2:$A$1093,0)),"") | L6: хост для аудио-опций, 3 слота | M6: =IF($C6="",0,IF($J6<>"Да",0,IF(ISNUMBER(SEARCH("Fashionware",$E6)),0,IF(COUNTIF('05 СНАРЯЖЕНИЕ'!$C$34:$C$53,$C6)>0,0,$G6)))) | N6: =IF($C6="",0,IF($J6<>"Да",0,IF(ISNUMBER(SEARCH("Fashionware",$E6)),$G6,0)))
B7: 3 | C7: Voice Stress Analyzer | D7: =IFERROR(INDEX('КАТАЛОГ'!$B$2:$B$1093,MATCH($C7,'КАТАЛОГ'!$A$2:$A$1093,0)),"") | E7: =IFERROR(INDEX('КАТАЛОГ'!$C$2:$C$1093,MATCH($C7,'КАТАЛОГ'!$A$2:$A$1093,0)),"") | G7: =IF($C7="",0,IF(ISNUMBER(SEARCH("Neuroport",$C7)),0,IFERROR(INDEX('КАТАЛОГ'!$R$2:$R$1093,MATCH($C7,'КАТАЛОГ'!$A$2:$A$1093,0)),0))) | H7: =IF($C7="",0,IF(ISNUMBER(SEARCH("Neuroport",$C7)),0,IFERROR(INDEX('КАТАЛОГ'!$M$2:$M$1093,MATCH($C7,'КАТАЛОГ'!$A$2:$A$1093,0)),0))) | I7: =IF($C7="",0,IF(OR(N($H7)=0,ISNUMBER(SEARCH("Fashionware",$E7))),0,IF(ISNUMBER(SEARCH("Borgware",$E7)),4,2))) | J7: Да | K7: =IFERROR(INDEX('КАТАЛОГ'!$N$2:$N$1093,MATCH($C7,'КАТАЛОГ'!$A$2:$A$1093,0)),"") | L7: +2 Human Perception и Interrogation, детектор лжи | M7: =IF($C7="",0,IF($J7<>"Да",0,IF(ISNUMBER(SEARCH("Fashionware",$E7)),0,IF(COUNTIF('05 СНАРЯЖЕНИЕ'!$C$34:$C$53,$C7)>0,0,$G7)))) | N7: =IF($C7="",0,IF($J7<>"Да",0,IF(ISNUMBER(SEARCH("Fashionware",$E7)),$G7,0)))
B8: 4 | C8: Amplified Hearing | D8: =IFERROR(INDEX('КАТАЛОГ'!$B$2:$B$1093,MATCH($C8,'КАТАЛОГ'!$A$2:$A$1093,0)),"") | E8: =IFERROR(INDEX('КАТАЛОГ'!$C$2:$C$1093,MATCH($C8,'КАТАЛОГ'!$A$2:$A$1093,0)),"") | G8: =IF($C8="",0,IF(ISNUMBER(SEARCH("Neuroport",$C8)),0,IFERROR(INDEX('КАТАЛОГ'!$R$2:$R$1093,MATCH($C8,'КАТАЛОГ'!$A$2:$A$1093,0)),0))) | H8: =IF($C8="",0,IF(ISNUMBER(SEARCH("Neuroport",$C8)),0,IFERROR(INDEX('КАТАЛОГ'!$M$2:$M$1093,MATCH($C8,'КАТАЛОГ'!$A$2:$A$1093,0)),0))) | I8: =IF($C8="",0,IF(OR(N($H8)=0,ISNUMBER(SEARCH("Fashionware",$E8))),0,IF(ISNUMBER(SEARCH("Borgware",$E8)),4,2))) | J8: Да | K8: =IFERROR(INDEX('КАТАЛОГ'!$N$2:$N$1093,MATCH($C8,'КАТАЛОГ'!$A$2:$A$1093,0)),"") | L8: +2 Perception на слух | M8: =IF($C8="",0,IF($J8<>"Да",0,IF(ISNUMBER(SEARCH("Fashionware",$E8)),0,IF(COUNTIF('05 СНАРЯЖЕНИЕ'!$C$34:$C$53,$C8)>0,0,$G8)))) | N8: =IF($C8="",0,IF($J8<>"Да",0,IF(ISNUMBER(SEARCH("Fashionware",$E8)),$G8,0)))
B9: 5 | C9: Toxin Binders | D9: =IFERROR(INDEX('КАТАЛОГ'!$B$2:$B$1093,MATCH($C9,'КАТАЛОГ'!$A$2:$A$1093,0)),"") | E9: =IFERROR(INDEX('КАТАЛОГ'!$C$2:$C$1093,MATCH($C9,'КАТАЛОГ'!$A$2:$A$1093,0)),"") | G9: =IF($C9="",0,IF(ISNUMBER(SEARCH("Neuroport",$C9)),0,IFERROR(INDEX('КАТАЛОГ'!$R$2:$R$1093,MATCH($C9,'КАТАЛОГ'!$A$2:$A$1093,0)),0))) | H9: =IF($C9="",0,IF(ISNUMBER(SEARCH("Neuroport",$C9)),0,IFERROR(INDEX('КАТАЛОГ'!$M$2:$M$1093,MATCH($C9,'КАТАЛОГ'!$A$2:$A$1093,0)),0))) | I9: =IF($C9="",0,IF(OR(N($H9)=0,ISNUMBER(SEARCH("Fashionware",$E9))),0,IF(ISNUMBER(SEARCH("Borgware",$E9)),4,2))) | J9: Да | K9: =IFERROR(INDEX('КАТАЛОГ'!$N$2:$N$1093,MATCH($C9,'КАТАЛОГ'!$A$2:$A$1093,0)),"") | L9: +2 Resist Torture/Drugs | M9: =IF($C9="",0,IF($J9<>"Да",0,IF(ISNUMBER(SEARCH("Fashionware",$E9)),0,IF(COUNTIF('05 СНАРЯЖЕНИЕ'!$C$34:$C$53,$C9)>0,0,$G9)))) | N9: =IF($C9="",0,IF($J9<>"Да",0,IF(ISNUMBER(SEARCH("Fashionware",$E9)),$G9,0)))
B10: 6 | C10: Biomonitor | D10: =IFERROR(INDEX('КАТАЛОГ'!$B$2:$B$1093,MATCH($C10,'КАТАЛОГ'!$A$2:$A$1093,0)),"") | E10: =IFERROR(INDEX('КАТАЛОГ'!$C$2:$C$1093,MATCH($C10,'КАТАЛОГ'!$A$2:$A$1093,0)),"") | G10: =IF($C10="",0,IF(ISNUMBER(SEARCH("Neuroport",$C10)),0,IFERROR(INDEX('КАТАЛОГ'!$R$2:$R$1093,MATCH($C10,'КАТАЛОГ'!$A$2:$A$1093,0)),0))) | H10: =IF($C10="",0,IF(ISNUMBER(SEARCH("Neuroport",$C10)),0,IFERROR(INDEX('КАТАЛОГ'!$M$2:$M$1093,MATCH($C10,'КАТАЛОГ'!$A$2:$A$1093,0)),0))) | I10: =IF($C10="",0,IF(OR(N($H10)=0,ISNUMBER(SEARCH("Fashionware",$E10))),0,IF(ISNUMBER(SEARCH("Borgware",$E10)),4,2))) | J10: Да | K10: =IFERROR(INDEX('КАТАЛОГ'!$N$2:$N$1093,MATCH($C10,'КАТАЛОГ'!$A$2:$A$1093,0)),"") | L10: Fashionware · пульс/температура на Агент | M10: =IF($C10="",0,IF($J10<>"Да",0,IF(ISNUMBER(SEARCH("Fashionware",$E10)),0,IF(COUNTIF('05 СНАРЯЖЕНИЕ'!$C$34:$C$53,$C10)>0,0,$G10)))) | N10: =IF($C10="",0,IF($J10<>"Да",0,IF(ISNUMBER(SEARCH("Fashionware",$E10)),$G10,0)))
B11: 7 | C11: Radio Communicator | D11: =IFERROR(INDEX('КАТАЛОГ'!$B$2:$B$1093,MATCH($C11,'КАТАЛОГ'!$A$2:$A$1093,0)),"") | E11: =IFERROR(INDEX('КАТАЛОГ'!$C$2:$C$1093,MATCH($C11,'КАТАЛОГ'!$A$2:$A$1093,0)),"") | G11: =IF($C11="",0,IF(ISNUMBER(SEARCH("Neuroport",$C11)),0,IFERROR(INDEX('КАТАЛОГ'!$R$2:$R$1093,MATCH($C11,'КАТАЛОГ'!$A$2:$A$1093,0)),0))) | H11: =IF($C11="",0,IF(ISNUMBER(SEARCH("Neuroport",$C11)),0,IFERROR(INDEX('КАТАЛОГ'!$M$2:$M$1093,MATCH($C11,'КАТАЛОГ'!$A$2:$A$1093,0)),0))) | I11: =IF($C11="",0,IF(OR(N($H11)=0,ISNUMBER(SEARCH("Fashionware",$E11))),0,IF(ISNUMBER(SEARCH("Borgware",$E11)),4,2))) | J11: Да | K11: =IFERROR(INDEX('КАТАЛОГ'!$N$2:$N$1093,MATCH($C11,'КАТАЛОГ'!$A$2:$A$1093,0)),"") | L11: Cyberaudio Option (3-й слот Suite): связь на 1 милю | M11: =IF($C11="",0,IF($J11<>"Да",0,IF(ISNUMBER(SEARCH("Fashionware",$E11)),0,IF(COUNTIF('05 СНАРЯЖЕНИЕ'!$C$34:$C$53,$C11)>0,0,$G11)))) | N11: =IF($C11="",0,IF($J11<>"Да",0,IF(ISNUMBER(SEARCH("Fashionware",$E11)),$G11,0)))
B12: 8 | C12: Light Tattoo | D12: =IFERROR(INDEX('КАТАЛОГ'!$B$2:$B$1093,MATCH($C12,'КАТАЛОГ'!$A$2:$A$1093,0)),"") | E12: =IFERROR(INDEX('КАТАЛОГ'!$C$2:$C$1093,MATCH($C12,'КАТАЛОГ'!$A$2:$A$1093,0)),"") | G12: =IF($C12="",0,IF(ISNUMBER(SEARCH("Neuroport",$C12)),0,IFERROR(INDEX('КАТАЛОГ'!$R$2:$R$1093,MATCH($C12,'КАТАЛОГ'!$A$2:$A$1093,0)),0))) | H12: =IF($C12="",0,IF(ISNUMBER(SEARCH("Neuroport",$C12)),0,IFERROR(INDEX('КАТАЛОГ'!$M$2:$M$1093,MATCH($C12,'КАТАЛОГ'!$A$2:$A$1093,0)),0))) | I12: =IF($C12="",0,IF(OR(N($H12)=0,ISNUMBER(SEARCH("Fashionware",$E12))),0,IF(ISNUMBER(SEARCH("Borgware",$E12)),4,2))) | J12: Да | K12: =IFERROR(INDEX('КАТАЛОГ'!$N$2:$N$1093,MATCH($C12,'КАТАЛОГ'!$A$2:$A$1093,0)),"") | L12: Fashionware: выцветшая татуировка-значок NCPD (0 HL, стиль-бюджет) | M12: =IF($C12="",0,IF($J12<>"Да",0,IF(ISNUMBER(SEARCH("Fashionware",$E12)),0,IF(COUNTIF('05 СНАРЯЖЕНИЕ'!$C$34:$C$53,$C12)>0,0,$G12)))) | N12: =IF($C12="",0,IF($J12<>"Да",0,IF(ISNUMBER(SEARCH("Fashionware",$E12)),$G12,0)))
B13: 9 | C13: EMP Threading | D13: =IFERROR(INDEX('КАТАЛОГ'!$B$2:$B$1093,MATCH($C13,'КАТАЛОГ'!$A$2:$A$1093,0)),"") | E13: =IFERROR(INDEX('КАТАЛОГ'!$C$2:$C$1093,MATCH($C13,'КАТАЛОГ'!$A$2:$A$1093,0)),"") | G13: =IF($C13="",0,IF(ISNUMBER(SEARCH("Neuroport",$C13)),0,IFERROR(INDEX('КАТАЛОГ'!$R$2:$R$1093,MATCH($C13,'КАТАЛОГ'!$A$2:$A$1093,0)),0))) | H13: =IF($C13="",0,IF(ISNUMBER(SEARCH("Neuroport",$C13)),0,IFERROR(INDEX('КАТАЛОГ'!$M$2:$M$1093,MATCH($C13,'КАТАЛОГ'!$A$2:$A$1093,0)),0))) | I13: =IF($C13="",0,IF(OR(N($H13)=0,ISNUMBER(SEARCH("Fashionware",$E13))),0,IF(ISNUMBER(SEARCH("Borgware",$E13)),4,2))) | J13: Да | K13: =IFERROR(INDEX('КАТАЛОГ'!$N$2:$N$1093,MATCH($C13,'КАТАЛОГ'!$A$2:$A$1093,0)),"") | L13: Fashionware: светящиеся линии на предплечье (0 HL) | M13: =IF($C13="",0,IF($J13<>"Да",0,IF(ISNUMBER(SEARCH("Fashionware",$E13)),0,IF(COUNTIF('05 СНАРЯЖЕНИЕ'!$C$34:$C$53,$C13)>0,0,$G13)))) | N13: =IF($C13="",0,IF($J13<>"Да",0,IF(ISNUMBER(SEARCH("Fashionware",$E13)),$G13,0)))
B14: 10 | D14: =IFERROR(INDEX('КАТАЛОГ'!$B$2:$B$1093,MATCH($C14,'КАТАЛОГ'!$A$2:$A$1093,0)),"") | E14: =IFERROR(INDEX('КАТАЛОГ'!$C$2:$C$1093,MATCH($C14,'КАТАЛОГ'!$A$2:$A$1093,0)),"") | G14: =IF($C14="",0,IF(ISNUMBER(SEARCH("Neuroport",$C14)),0,IFERROR(INDEX('КАТАЛОГ'!$R$2:$R$1093,MATCH($C14,'КАТАЛОГ'!$A$2:$A$1093,0)),0))) | H14: =IF($C14="",0,IF(ISNUMBER(SEARCH("Neuroport",$C14)),0,IFERROR(INDEX('КАТАЛОГ'!$M$2:$M$1093,MATCH($C14,'КАТАЛОГ'!$A$2:$A$1093,0)),0))) | I14: =IF($C14="",0,IF(OR(N($H14)=0,ISNUMBER(SEARCH("Fashionware",$E14))),0,IF(ISNUMBER(SEARCH("Borgware",$E14)),4,2))) | J14: Нет | K14: =IFERROR(INDEX('КАТАЛОГ'!$N$2:$N$1093,MATCH($C14,'КАТАЛОГ'!$A$2:$A$1093,0)),"") | L14: =IFERROR(LEFT(INDEX('КАТАЛОГ'!$T$2:$T$1093,MATCH($C14,'КАТАЛОГ'!$A$2:$A$1093,0)),70),"") | M14: =IF($C14="",0,IF($J14<>"Да",0,IF(ISNUMBER(SEARCH("Fashionware",$E14)),0,IF(COUNTIF('05 СНАРЯЖЕНИЕ'!$C$34:$C$53,$C14)>0,0,$G14)))) | N14: =IF($C14="",0,IF($J14<>"Да",0,IF(ISNUMBER(SEARCH("Fashionware",$E14)),$G14,0)))
B15: 11 | D15: =IFERROR(INDEX('КАТАЛОГ'!$B$2:$B$1093,MATCH($C15,'КАТАЛОГ'!$A$2:$A$1093,0)),"") | E15: =IFERROR(INDEX('КАТАЛОГ'!$C$2:$C$1093,MATCH($C15,'КАТАЛОГ'!$A$2:$A$1093,0)),"") | G15: =IF($C15="",0,IF(ISNUMBER(SEARCH("Neuroport",$C15)),0,IFERROR(INDEX('КАТАЛОГ'!$R$2:$R$1093,MATCH($C15,'КАТАЛОГ'!$A$2:$A$1093,0)),0))) | H15: =IF($C15="",0,IF(ISNUMBER(SEARCH("Neuroport",$C15)),0,IFERROR(INDEX('КАТАЛОГ'!$M$2:$M$1093,MATCH($C15,'КАТАЛОГ'!$A$2:$A$1093,0)),0))) | I15: =IF($C15="",0,IF(OR(N($H15)=0,ISNUMBER(SEARCH("Fashionware",$E15))),0,IF(ISNUMBER(SEARCH("Borgware",$E15)),4,2))) | J15: Нет | K15: =IFERROR(INDEX('КАТАЛОГ'!$N$2:$N$1093,MATCH($C15,'КАТАЛОГ'!$A$2:$A$1093,0)),"") | L15: =IFERROR(LEFT(INDEX('КАТАЛОГ'!$T$2:$T$1093,MATCH($C15,'КАТАЛОГ'!$A$2:$A$1093,0)),70),"") | M15: =IF($C15="",0,IF($J15<>"Да",0,IF(ISNUMBER(SEARCH("Fashionware",$E15)),0,IF(COUNTIF('05 СНАРЯЖЕНИЕ'!$C$34:$C$53,$C15)>0,0,$G15)))) | N15: =IF($C15="",0,IF($J15<>"Да",0,IF(ISNUMBER(SEARCH("Fashionware",$E15)),$G15,0)))
B16: 12 | D16: =IFERROR(INDEX('КАТАЛОГ'!$B$2:$B$1093,MATCH($C16,'КАТАЛОГ'!$A$2:$A$1093,0)),"") | E16: =IFERROR(INDEX('КАТАЛОГ'!$C$2:$C$1093,MATCH($C16,'КАТАЛОГ'!$A$2:$A$1093,0)),"") | G16: =IF($C16="",0,IF(ISNUMBER(SEARCH("Neuroport",$C16)),0,IFERROR(INDEX('КАТАЛОГ'!$R$2:$R$1093,MATCH($C16,'КАТАЛОГ'!$A$2:$A$1093,0)),0))) | H16: =IF($C16="",0,IF(ISNUMBER(SEARCH("Neuroport",$C16)),0,IFERROR(INDEX('КАТАЛОГ'!$M$2:$M$1093,MATCH($C16,'КАТАЛОГ'!$A$2:$A$1093,0)),0))) | I16: =IF($C16="",0,IF(OR(N($H16)=0,ISNUMBER(SEARCH("Fashionware",$E16))),0,IF(ISNUMBER(SEARCH("Borgware",$E16)),4,2))) | J16: Нет | K16: =IFERROR(INDEX('КАТАЛОГ'!$N$2:$N$1093,MATCH($C16,'КАТАЛОГ'!$A$2:$A$1093,0)),"") | L16: =IFERROR(LEFT(INDEX('КАТАЛОГ'!$T$2:$T$1093,MATCH($C16,'КАТАЛОГ'!$A$2:$A$1093,0)),70),"") | M16: =IF($C16="",0,IF($J16<>"Да",0,IF(ISNUMBER(SEARCH("Fashionware",$E16)),0,IF(COUNTIF('05 СНАРЯЖЕНИЕ'!$C$34:$C$53,$C16)>0,0,$G16)))) | N16: =IF($C16="",0,IF($J16<>"Да",0,IF(ISNUMBER(SEARCH("Fashionware",$E16)),$G16,0)))
B17: 13 | D17: =IFERROR(INDEX('КАТАЛОГ'!$B$2:$B$1093,MATCH($C17,'КАТАЛОГ'!$A$2:$A$1093,0)),"") | E17: =IFERROR(INDEX('КАТАЛОГ'!$C$2:$C$1093,MATCH($C17,'КАТАЛОГ'!$A$2:$A$1093,0)),"") | G17: =IF($C17="",0,IF(ISNUMBER(SEARCH("Neuroport",$C17)),0,IFERROR(INDEX('КАТАЛОГ'!$R$2:$R$1093,MATCH($C17,'КАТАЛОГ'!$A$2:$A$1093,0)),0))) | H17: =IF($C17="",0,IF(ISNUMBER(SEARCH("Neuroport",$C17)),0,IFERROR(INDEX('КАТАЛОГ'!$M$2:$M$1093,MATCH($C17,'КАТАЛОГ'!$A$2:$A$1093,0)),0))) | I17: =IF($C17="",0,IF(OR(N($H17)=0,ISNUMBER(SEARCH("Fashionware",$E17))),0,IF(ISNUMBER(SEARCH("Borgware",$E17)),4,2))) | J17: Нет | K17: =IFERROR(INDEX('КАТАЛОГ'!$N$2:$N$1093,MATCH($C17,'КАТАЛОГ'!$A$2:$A$1093,0)),"") | L17: =IFERROR(LEFT(INDEX('КАТАЛОГ'!$T$2:$T$1093,MATCH($C17,'КАТАЛОГ'!$A$2:$A$1093,0)),70),"") | M17: =IF($C17="",0,IF($J17<>"Да",0,IF(ISNUMBER(SEARCH("Fashionware",$E17)),0,IF(COUNTIF('05 СНАРЯЖЕНИЕ'!$C$34:$C$53,$C17)>0,0,$G17)))) | N17: =IF($C17="",0,IF($J17<>"Да",0,IF(ISNUMBER(SEARCH("Fashionware",$E17)),$G17,0)))
B18: 14 | D18: =IFERROR(INDEX('КАТАЛОГ'!$B$2:$B$1093,MATCH($C18,'КАТАЛОГ'!$A$2:$A$1093,0)),"") | E18: =IFERROR(INDEX('КАТАЛОГ'!$C$2:$C$1093,MATCH($C18,'КАТАЛОГ'!$A$2:$A$1093,0)),"") | G18: =IF($C18="",0,IF(ISNUMBER(SEARCH("Neuroport",$C18)),0,IFERROR(INDEX('КАТАЛОГ'!$R$2:$R$1093,MATCH($C18,'КАТАЛОГ'!$A$2:$A$1093,0)),0))) | H18: =IF($C18="",0,IF(ISNUMBER(SEARCH("Neuroport",$C18)),0,IFERROR(INDEX('КАТАЛОГ'!$M$2:$M$1093,MATCH($C18,'КАТАЛОГ'!$A$2:$A$1093,0)),0))) | I18: =IF($C18="",0,IF(OR(N($H18)=0,ISNUMBER(SEARCH("Fashionware",$E18))),0,IF(ISNUMBER(SEARCH("Borgware",$E18)),4,2))) | J18: Нет | K18: =IFERROR(INDEX('КАТАЛОГ'!$N$2:$N$1093,MATCH($C18,'КАТАЛОГ'!$A$2:$A$1093,0)),"") | L18: =IFERROR(LEFT(INDEX('КАТАЛОГ'!$T$2:$T$1093,MATCH($C18,'КАТАЛОГ'!$A$2:$A$1093,0)),70),"") | M18: =IF($C18="",0,IF($J18<>"Да",0,IF(ISNUMBER(SEARCH("Fashionware",$E18)),0,IF(COUNTIF('05 СНАРЯЖЕНИЕ'!$C$34:$C$53,$C18)>0,0,$G18)))) | N18: =IF($C18="",0,IF($J18<>"Да",0,IF(ISNUMBER(SEARCH("Fashionware",$E18)),$G18,0)))
B19: 15 | D19: =IFERROR(INDEX('КАТАЛОГ'!$B$2:$B$1093,MATCH($C19,'КАТАЛОГ'!$A$2:$A$1093,0)),"") | E19: =IFERROR(INDEX('КАТАЛОГ'!$C$2:$C$1093,MATCH($C19,'КАТАЛОГ'!$A$2:$A$1093,0)),"") | G19: =IF($C19="",0,IF(ISNUMBER(SEARCH("Neuroport",$C19)),0,IFERROR(INDEX('КАТАЛОГ'!$R$2:$R$1093,MATCH($C19,'КАТАЛОГ'!$A$2:$A$1093,0)),0))) | H19: =IF($C19="",0,IF(ISNUMBER(SEARCH("Neuroport",$C19)),0,IFERROR(INDEX('КАТАЛОГ'!$M$2:$M$1093,MATCH($C19,'КАТАЛОГ'!$A$2:$A$1093,0)),0))) | I19: =IF($C19="",0,IF(OR(N($H19)=0,ISNUMBER(SEARCH("Fashionware",$E19))),0,IF(ISNUMBER(SEARCH("Borgware",$E19)),4,2))) | J19: Нет | K19: =IFERROR(INDEX('КАТАЛОГ'!$N$2:$N$1093,MATCH($C19,'КАТАЛОГ'!$A$2:$A$1093,0)),"") | L19: =IFERROR(LEFT(INDEX('КАТАЛОГ'!$T$2:$T$1093,MATCH($C19,'КАТАЛОГ'!$A$2:$A$1093,0)),70),"") | M19: =IF($C19="",0,IF($J19<>"Да",0,IF(ISNUMBER(SEARCH("Fashionware",$E19)),0,IF(COUNTIF('05 СНАРЯЖЕНИЕ'!$C$34:$C$53,$C19)>0,0,$G19)))) | N19: =IF($C19="",0,IF($J19<>"Да",0,IF(ISNUMBER(SEARCH("Fashionware",$E19)),$G19,0)))
B20: 16 | D20: =IFERROR(INDEX('КАТАЛОГ'!$B$2:$B$1093,MATCH($C20,'КАТАЛОГ'!$A$2:$A$1093,0)),"") | E20: =IFERROR(INDEX('КАТАЛОГ'!$C$2:$C$1093,MATCH($C20,'КАТАЛОГ'!$A$2:$A$1093,0)),"") | G20: =IF($C20="",0,IF(ISNUMBER(SEARCH("Neuroport",$C20)),0,IFERROR(INDEX('КАТАЛОГ'!$R$2:$R$1093,MATCH($C20,'КАТАЛОГ'!$A$2:$A$1093,0)),0))) | H20: =IF($C20="",0,IF(ISNUMBER(SEARCH("Neuroport",$C20)),0,IFERROR(INDEX('КАТАЛОГ'!$M$2:$M$1093,MATCH($C20,'КАТАЛОГ'!$A$2:$A$1093,0)),0))) | I20: =IF($C20="",0,IF(OR(N($H20)=0,ISNUMBER(SEARCH("Fashionware",$E20))),0,IF(ISNUMBER(SEARCH("Borgware",$E20)),4,2))) | J20: Нет | K20: =IFERROR(INDEX('КАТАЛОГ'!$N$2:$N$1093,MATCH($C20,'КАТАЛОГ'!$A$2:$A$1093,0)),"") | L20: =IFERROR(LEFT(INDEX('КАТАЛОГ'!$T$2:$T$1093,MATCH($C20,'КАТАЛОГ'!$A$2:$A$1093,0)),70),"") | M20: =IF($C20="",0,IF($J20<>"Да",0,IF(ISNUMBER(SEARCH("Fashionware",$E20)),0,IF(COUNTIF('05 СНАРЯЖЕНИЕ'!$C$34:$C$53,$C20)>0,0,$G20)))) | N20: =IF($C20="",0,IF($J20<>"Да",0,IF(ISNUMBER(SEARCH("Fashionware",$E20)),$G20,0)))
B21: 17 | D21: =IFERROR(INDEX('КАТАЛОГ'!$B$2:$B$1093,MATCH($C21,'КАТАЛОГ'!$A$2:$A$1093,0)),"") | E21: =IFERROR(INDEX('КАТАЛОГ'!$C$2:$C$1093,MATCH($C21,'КАТАЛОГ'!$A$2:$A$1093,0)),"") | G21: =IF($C21="",0,IF(ISNUMBER(SEARCH("Neuroport",$C21)),0,IFERROR(INDEX('КАТАЛОГ'!$R$2:$R$1093,MATCH($C21,'КАТАЛОГ'!$A$2:$A$1093,0)),0))) | H21: =IF($C21="",0,IF(ISNUMBER(SEARCH("Neuroport",$C21)),0,IFERROR(INDEX('КАТАЛОГ'!$M$2:$M$1093,MATCH($C21,'КАТАЛОГ'!$A$2:$A$1093,0)),0))) | I21: =IF($C21="",0,IF(OR(N($H21)=0,ISNUMBER(SEARCH("Fashionware",$E21))),0,IF(ISNUMBER(SEARCH("Borgware",$E21)),4,2))) | J21: Нет | K21: =IFERROR(INDEX('КАТАЛОГ'!$N$2:$N$1093,MATCH($C21,'КАТАЛОГ'!$A$2:$A$1093,0)),"") | L21: =IFERROR(LEFT(INDEX('КАТАЛОГ'!$T$2:$T$1093,MATCH($C21,'КАТАЛОГ'!$A$2:$A$1093,0)),70),"") | M21: =IF($C21="",0,IF($J21<>"Да",0,IF(ISNUMBER(SEARCH("Fashionware",$E21)),0,IF(COUNTIF('05 СНАРЯЖЕНИЕ'!$C$34:$C$53,$C21)>0,0,$G21)))) | N21: =IF($C21="",0,IF($J21<>"Да",0,IF(ISNUMBER(SEARCH("Fashionware",$E21)),$G21,0)))
B22: 18 | D22: =IFERROR(INDEX('КАТАЛОГ'!$B$2:$B$1093,MATCH($C22,'КАТАЛОГ'!$A$2:$A$1093,0)),"") | E22: =IFERROR(INDEX('КАТАЛОГ'!$C$2:$C$1093,MATCH($C22,'КАТАЛОГ'!$A$2:$A$1093,0)),"") | G22: =IF($C22="",0,IF(ISNUMBER(SEARCH("Neuroport",$C22)),0,IFERROR(INDEX('КАТАЛОГ'!$R$2:$R$1093,MATCH($C22,'КАТАЛОГ'!$A$2:$A$1093,0)),0))) | H22: =IF($C22="",0,IF(ISNUMBER(SEARCH("Neuroport",$C22)),0,IFERROR(INDEX('КАТАЛОГ'!$M$2:$M$1093,MATCH($C22,'КАТАЛОГ'!$A$2:$A$1093,0)),0))) | I22: =IF($C22="",0,IF(OR(N($H22)=0,ISNUMBER(SEARCH("Fashionware",$E22))),0,IF(ISNUMBER(SEARCH("Borgware",$E22)),4,2))) | J22: Нет | K22: =IFERROR(INDEX('КАТАЛОГ'!$N$2:$N$1093,MATCH($C22,'КАТАЛОГ'!$A$2:$A$1093,0)),"") | L22: =IFERROR(LEFT(INDEX('КАТАЛОГ'!$T$2:$T$1093,MATCH($C22,'КАТАЛОГ'!$A$2:$A$1093,0)),70),"") | M22: =IF($C22="",0,IF($J22<>"Да",0,IF(ISNUMBER(SEARCH("Fashionware",$E22)),0,IF(COUNTIF('05 СНАРЯЖЕНИЕ'!$C$34:$C$53,$C22)>0,0,$G22)))) | N22: =IF($C22="",0,IF($J22<>"Да",0,IF(ISNUMBER(SEARCH("Fashionware",$E22)),$G22,0)))
B23: 19 | D23: =IFERROR(INDEX('КАТАЛОГ'!$B$2:$B$1093,MATCH($C23,'КАТАЛОГ'!$A$2:$A$1093,0)),"") | E23: =IFERROR(INDEX('КАТАЛОГ'!$C$2:$C$1093,MATCH($C23,'КАТАЛОГ'!$A$2:$A$1093,0)),"") | G23: =IF($C23="",0,IF(ISNUMBER(SEARCH("Neuroport",$C23)),0,IFERROR(INDEX('КАТАЛОГ'!$R$2:$R$1093,MATCH($C23,'КАТАЛОГ'!$A$2:$A$1093,0)),0))) | H23: =IF($C23="",0,IF(ISNUMBER(SEARCH("Neuroport",$C23)),0,IFERROR(INDEX('КАТАЛОГ'!$M$2:$M$1093,MATCH($C23,'КАТАЛОГ'!$A$2:$A$1093,0)),0))) | I23: =IF($C23="",0,IF(OR(N($H23)=0,ISNUMBER(SEARCH("Fashionware",$E23))),0,IF(ISNUMBER(SEARCH("Borgware",$E23)),4,2))) | J23: Нет | K23: =IFERROR(INDEX('КАТАЛОГ'!$N$2:$N$1093,MATCH($C23,'КАТАЛОГ'!$A$2:$A$1093,0)),"") | L23: =IFERROR(LEFT(INDEX('КАТАЛОГ'!$T$2:$T$1093,MATCH($C23,'КАТАЛОГ'!$A$2:$A$1093,0)),70),"") | M23: =IF($C23="",0,IF($J23<>"Да",0,IF(ISNUMBER(SEARCH("Fashionware",$E23)),0,IF(COUNTIF('05 СНАРЯЖЕНИЕ'!$C$34:$C$53,$C23)>0,0,$G23)))) | N23: =IF($C23="",0,IF($J23<>"Да",0,IF(ISNUMBER(SEARCH("Fashionware",$E23)),$G23,0)))
B24: 20 | D24: =IFERROR(INDEX('КАТАЛОГ'!$B$2:$B$1093,MATCH($C24,'КАТАЛОГ'!$A$2:$A$1093,0)),"") | E24: =IFERROR(INDEX('КАТАЛОГ'!$C$2:$C$1093,MATCH($C24,'КАТАЛОГ'!$A$2:$A$1093,0)),"") | G24: =IF($C24="",0,IF(ISNUMBER(SEARCH("Neuroport",$C24)),0,IFERROR(INDEX('КАТАЛОГ'!$R$2:$R$1093,MATCH($C24,'КАТАЛОГ'!$A$2:$A$1093,0)),0))) | H24: =IF($C24="",0,IF(ISNUMBER(SEARCH("Neuroport",$C24)),0,IFERROR(INDEX('КАТАЛОГ'!$M$2:$M$1093,MATCH($C24,'КАТАЛОГ'!$A$2:$A$1093,0)),0))) | I24: =IF($C24="",0,IF(OR(N($H24)=0,ISNUMBER(SEARCH("Fashionware",$E24))),0,IF(ISNUMBER(SEARCH("Borgware",$E24)),4,2))) | J24: Нет | K24: =IFERROR(INDEX('КАТАЛОГ'!$N$2:$N$1093,MATCH($C24,'КАТАЛОГ'!$A$2:$A$1093,0)),"") | L24: =IFERROR(LEFT(INDEX('КАТАЛОГ'!$T$2:$T$1093,MATCH($C24,'КАТАЛОГ'!$A$2:$A$1093,0)),70),"") | M24: =IF($C24="",0,IF($J24<>"Да",0,IF(ISNUMBER(SEARCH("Fashionware",$E24)),0,IF(COUNTIF('05 СНАРЯЖЕНИЕ'!$C$34:$C$53,$C24)>0,0,$G24)))) | N24: =IF($C24="",0,IF($J24<>"Да",0,IF(ISNUMBER(SEARCH("Fashionware",$E24)),$G24,0)))
B25: ИТОГО (ТОЛЬКО ОТМЕЧЕННЫЕ «ДА») | G25: =SUM($M$5:$M$24)+SUM($N$5:$N$24) | H25: =SUMIF($J$5:$J$24,"Да",$H$5:$H$24) | I25: =SUMIF($J$5:$J$24,"Да",$I$5:$I$24) | J25: HL / срез | K25: → переносится в HUMANITY на листе 02 | M25: =SUM($M$5:$M$24) | N25: =SUM($N$5:$N$24)
B26: NEUROPORT УСТАНОВЛЕН (2070) | E26: Да | F26: =IF(AND($E$26="Нет",COUNTIF($J$5:$J$24,"Да")>0),"⚠ По правилам 2070-х любой немедицинский хром требует Neuroport (CEMK стр. 26)","✔ ок. Neuroport при создании: 0 €$, 0 HL, максимум Humanity не режется (в игре установка — 1000 €$ и 7 HL в среднем)")
B27: NEUROPORT ДАЁТ: Neural Link (5 слотов Neuralware Options) · Holophone · Biomonitor · Virtu · HUD/Chyron (перевод и субтитры на ходу) · 2 чип-слота под шарды · Personal Link (Interface Plug). Порт под кибердеку — 100 €$ и 3 (1d6) HL; диапазон сети 20 м, до нейропортов — 50 м.
B28: ЖЁСТКИЕ ЛИМИТЫ: одно Speedware на пользователя · один Cyberdeck подключён за раз · цибер-оружие в руке считается имплантом и требует слот(ы) киберруки. Эффекты смотри в КАТАЛОГЕ.
B30: Ⅰ · HUMANITY · ЧЕЛОВЕЧНОСТЬ, ХЛ, ТЕРАПИЯ
B31: БАЗА (EMP × 10) | D31: ='02 ОСНОВА'!$D$31 | E31: От исходной EMP (лист 02, колонка «ЗНАЧ.»).
B32: СРЕЗ МАКСИМУМА ЗА ХРОМ | D32: ='02 ОСНОВА'!$D$32 | E32: Этот же срез стоит в колонке «СРЕЗ» выше. Fashionware и стартовый Neuroport не режут максимум.
B33: HUMANITY МАКСИМУМ | D33: ='02 ОСНОВА'!$D$33 | E33: База минус срез. Вернуть выше максимума нельзя — только снимать хром.
B34: HL ВСЕГО (СРЕДНЕЕ) | D34: ='02 ОСНОВА'!$D$34 | E34: Сумма средних HL установленного хрома. Твоё дом-правило: 7 (2d6) = −7.
B35: ВОССТАНОВЛЕНО (ТЕРАПИЯ/ОПЫТ) | D35: ='02 ОСНОВА'!$D$35 | E35: Правится на листе 02, ячейка D35: терапия + Humanity Gain по CEMK.
B36: HUMANITY ТЕКУЩАЯ | D36: ='02 ОСНОВА'!$D$36 | E36: База − HL + восстановленное, но не выше максимума.
B37: EMP ТЕКУЩАЯ | D37: ='02 ОСНОВА'!$D$37 | E37: Каждый раз, когда десяток Humanity падает — падает и EMP.
B38: СТАТУС | D38: ='02 ОСНОВА'!$D$38 | E38: Humanity < 0 = киберпсихоз: лист забирает GM.
B39: ШКАЛА HUMANITY | D39: ='02 ОСНОВА'!$D$36 | E39: =REPT("█",MAX(0,MIN(40,ROUND($D$39/2,0))))&REPT("░",MAX(0,40-MIN(40,ROUND($D$39/2,0))))
B41: Ⅱ · ТЕРАПИЯ · 1 НЕДЕЛЯ ЗА СЕАНС (CP:R СТР. 229) · MEDTECH НЕ ЛЕЧИТ СЕБЯ САМ
B42: ТИП | D42: ЦЕНА | E42: DV / МАТЕРИАЛЫ | G42: ЭФФЕКТ
...

Sheet 05 СНАРЯЖЕНИЕ
B1: СНАРЯЖЕНИЕ ▚ БЮДЖЕТ 2550 €$ + 800 €$ НА СТИЛЬ ▚ ОРУЖИЕ · БРОНЯ · ИНВЕНТАРЬ · КАССА
B2: НАЗВАНИЯ БЕРУТСЯ ИЗ КАТАЛОГА — ЦЕНА, УРОН И ШТРАФЫ ПОДТЯНУТСЯ АВТОМАТИЧЕСКИ. ЕСЛИ ВЕЩИ В КАТАЛОГЕ НЕТ — ВПИШИ СВОЮ ЦЕНУ В СТОЛБЕЦ «ЦЕНА СВОЯ».
B3: СТАРТ: ОРУЖИЕ, БРОНЯ, СНАРЯЖЕНИЕ, ХРОМ (€$) | E3: 2550 | F3: ПОТРАЧЕНО | G3: =$H$54+SUM('04 ХРОМ'!$M$5:$M$24)+SUM($O$21:$O$26)-($G$4-SUM('04 ХРОМ'!$N$5:$N$24)) | H3: ОСТАТОК | I3: =$E$3-$G$3 | J3: Копятся из трёх мест: инвентарь (Ⅲ), броня (Ⅱ) и установленный хром (лист 04). Что уже вписано в инвентарь, второй раз не считается.
B4: СТАРТ: СТИЛЬ — FASHION И FASHIONWARE (€$) | E4: 800 | F4: ПОТРАЧЕНО | G4: =SUMPRODUCT(($D$34:$D$53="Мода")*$I$34:$I$53)+SUMPRODUCT(($E$34:$E$53="Fashionware")*$I$34:$I$53)+SUM('04 ХРОМ'!$N$5:$N$24) | H4: ОСТАТОК | I4: =$E$4-$G$4 | J4: Одежда (категория «Мода»), Fashionware из инвентаря и Fashionware-хром с листа 04.
B5: НАЛИЧНЫЕ €$ (АВТО) | D5: =$I$3+SUM($E$58:$E$77) | E5: ПРОВЕРКА БЮДЖЕТА | F5: =IF(OR($I$3<0,$I$4<0),"✖ стартовые бюджеты превышены — согласуй с GM","✔ в рамках стартовых бюджетов: инвентарь + броня + хром") | I5: Остаток бюджета снаряжения (2 550 €$) остаётся при тебе наличными (CP:R стр. 104: «You keep anything you don’t spend»), а остаток 800 €$ на моду и фэшн-хром сгорает. +1500 €$ «от корпорации» — только на импланты, и вместе с обязательным Neural Link.
B7: Ⅰ · ОРУЖИЕ · СТОЛБЕЦ «В РУКАХ 1–4» ВЫНОСИТ ОРУЖИЕ НА ЛИСТ 02
B8: № | C8: НАЗВАНИЕ | D8: ТИП | E8: НАВЫК | F8: УРОН | G8: ROF | H8: МАГ. | I8: ПАТРОНЫ | J8: КАЧЕСТВО | K8: В РУКАХ 1–4 | L8: БАЗА АТАКИ | M8: ЗАМЕТКИ
B9: 1 | C9: Con Arms Unity | D9: =IFERROR(INDEX('КАТАЛОГ'!$C$2:$C$1093,MATCH($C9,'КАТАЛОГ'!$A$2:$A$1093,0)),"") | E9: =IFERROR(INDEX('КАТАЛОГ'!$D$2:$D$1093,MATCH($C9,'КАТАЛОГ'!$A$2:$A$1093,0)),"") | F9: =IFERROR(INDEX('КАТАЛОГ'!$E$2:$E$1093,MATCH($C9,'КАТАЛОГ'!$A$2:$A$1093,0)),"") | G9: =IFERROR(INDEX('КАТАЛОГ'!$F$2:$F$1093,MATCH($C9,'КАТАЛОГ'!$A$2:$A$1093,0)),"") | H9: =IFERROR(INDEX('КАТАЛОГ'!$G$2:$G$1093,MATCH($C9,'КАТАЛОГ'!$A$2:$A$1093,0)),"") | I9: Basic ×40 | J9: Standard | K9: 1 | L9: =IF($C9="","",IFERROR(INDEX('03 НАВЫКИ'!$I$5:$I$76,MATCH($E9,'03 НАВЫКИ'!$C$5:$C$76,0))+IF($J9="Excellent",1,IF($J9="Poor",-1,0)),0)) | M9: Табельный. Power Rebuild: криты +5 урона
B10: 2 | C10: Rostović DB-2 Satara | D10: =IFERROR(INDEX('КАТАЛОГ'!$C$2:$C$1093,MATCH($C10,'КАТАЛОГ'!$A$2:$A$1093,0)),"") | E10: =IFERROR(INDEX('КАТАЛОГ'!$D$2:$D$1093,MATCH($C10,'КАТАЛОГ'!$A$2:$A$1093,0)),"") | F10: =IFERROR(INDEX('КАТАЛОГ'!$E$2:$E$1093,MATCH($C10,'КАТАЛОГ'!$A$2:$A$1093,0)),"") | G10: =IFERROR(INDEX('КАТАЛОГ'!$F$2:$F$1093,MATCH($C10,'КАТАЛОГ'!$A$2:$A$1093,0)),"") | H10: =IFERROR(INDEX('КАТАЛОГ'!$G$2:$G$1093,MATCH($C10,'КАТАЛОГ'!$A$2:$A$1093,0)),"") | I10: Basic ×20 | J10: Standard | K10: 2 | L10: =IF($C10="","",IFERROR(INDEX('03 НАВЫКИ'!$I$5:$I$76,MATCH($E10,'03 НАВЫКИ'!$C$5:$C$76,0))+IF($J10="Excellent",1,IF($J10="Poor",-1,0)),0)) | M10: Tech Rebuild: зарядка → половина SP и стрельба через тонкие укрытия
B11: 3 | D11: =IFERROR(INDEX('КАТАЛОГ'!$C$2:$C$1093,MATCH($C11,'КАТАЛОГ'!$A$2:$A$1093,0)),"") | E11: =IFERROR(INDEX('КАТАЛОГ'!$D$2:$D$1093,MATCH($C11,'КАТАЛОГ'!$A$2:$A$1093,0)),"") | F11: =IFERROR(INDEX('КАТАЛОГ'!$E$2:$E$1093,MATCH($C11,'КАТАЛОГ'!$A$2:$A$1093,0)),"") | G11: =IFERROR(INDEX('КАТАЛОГ'!$F$2:$F$1093,MATCH($C11,'КАТАЛОГ'!$A$2:$A$1093,0)),"") | H11: =IFERROR(INDEX('КАТАЛОГ'!$G$2:$G$1093,MATCH($C11,'КАТАЛОГ'!$A$2:$A$1093,0)),"") | J11: Standard | L11: =IF($C11="","",IFERROR(INDEX('03 НАВЫКИ'!$I$5:$I$76,MATCH($E11,'03 НАВЫКИ'!$C$5:$C$76,0))+IF($J11="Excellent",1,IF($J11="Poor",-1,0)),0))
B12: 4 | D12: =IFERROR(INDEX('КАТАЛОГ'!$C$2:$C$1093,MATCH($C12,'КАТАЛОГ'!$A$2:$A$1093,0)),"") | E12: =IFERROR(INDEX('КАТАЛОГ'!$D$2:$D$1093,MATCH($C12,'КАТАЛОГ'!$A$2:$A$1093,0)),"") | F12: =IFERROR(INDEX('КАТАЛОГ'!$E$2:$E$1093,MATCH($C12,'КАТАЛОГ'!$A$2:$A$1093,0)),"") | G12: =IFERROR(INDEX('КАТАЛОГ'!$F$2:$F$1093,MATCH($C12,'КАТАЛОГ'!$A$2:$A$1093,0)),"") | H12: =IFERROR(INDEX('КАТАЛОГ'!$G$2:$G$1093,MATCH($C12,'КАТАЛОГ'!$A$2:$A$1093,0)),"") | J12: Standard | L12: =IF($C12="","",IFERROR(INDEX('03 НАВЫКИ'!$I$5:$I$76,MATCH($E12,'03 НАВЫКИ'!$C$5:$C$76,0))+IF($J12="Excellent",1,IF($J12="Poor",-1,0)),0))
B13: 5 | D13: =IFERROR(INDEX('КАТАЛОГ'!$C$2:$C$1093,MATCH($C13,'КАТАЛОГ'!$A$2:$A$1093,0)),"") | E13: =IFERROR(INDEX('КАТАЛОГ'!$D$2:$D$1093,MATCH($C13,'КАТАЛОГ'!$A$2:$A$1093,0)),"") | F13: =IFERROR(INDEX('КАТАЛОГ'!$E$2:$E$1093,MATCH($C13,'КАТАЛОГ'!$A$2:$A$1093,0)),"") | G13: =IFERROR(INDEX('КАТАЛОГ'!$F$2:$F$1093,MATCH($C13,'КАТАЛОГ'!$A$2:$A$1093,0)),"") | H13: =IFERROR(INDEX('КАТАЛОГ'!$G$2:$G$1093,MATCH($C13,'КАТАЛОГ'!$A$2:$A$1093,0)),"") | J13: Standard | L13: =IF($C13="","",IFERROR(INDEX('03 НАВЫКИ'!$I$5:$I$76,MATCH($E13,'03 НАВЫКИ'!$C$5:$C$76,0))+IF($J13="Excellent",1,IF($J13="Poor",-1,0)),0))
B14: 6 | D14: =IFERROR(INDEX('КАТАЛОГ'!$C$2:$C$1093,MATCH($C14,'КАТАЛОГ'!$A$2:$A$1093,0)),"") | E14: =IFERROR(INDEX('КАТАЛОГ'!$D$2:$D$1093,MATCH($C14,'КАТАЛОГ'!$A$2:$A$1093,0)),"") | F14: =IFERROR(INDEX('КАТАЛОГ'!$E$2:$E$1093,MATCH($C14,'КАТАЛОГ'!$A$2:$A$1093,0)),"") | G14: =IFERROR(INDEX('КАТАЛОГ'!$F$2:$F$1093,MATCH($C14,'КАТАЛОГ'!$A$2:$A$1093,0)),"") | H14: =IFERROR(INDEX('КАТАЛОГ'!$G$2:$G$1093,MATCH($C14,'КАТАЛОГ'!$A$2:$A$1093,0)),"") | J14: Standard | L14: =IF($C14="","",IFERROR(INDEX('03 НАВЫКИ'!$I$5:$I$76,MATCH($E14,'03 НАВЫКИ'!$C$5:$C$76,0))+IF($J14="Excellent",1,IF($J14="Poor",-1,0)),0))
B15: 7 | D15: =IFERROR(INDEX('КАТАЛОГ'!$C$2:$C$1093,MATCH($C15,'КАТАЛОГ'!$A$2:$A$1093,0)),"") | E15: =IFERROR(INDEX('КАТАЛОГ'!$D$2:$D$1093,MATCH($C15,'КАТАЛОГ'!$A$2:$A$1093,0)),"") | F15: =IFERROR(INDEX('КАТАЛОГ'!$E$2:$E$1093,MATCH($C15,'КАТАЛОГ'!$A$2:$A$1093,0)),"") | G15: =IFERROR(INDEX('КАТАЛОГ'!$F$2:$F$1093,MATCH($C15,'КАТАЛОГ'!$A$2:$A$1093,0)),"") | H15: =IFERROR(INDEX('КАТАЛОГ'!$G$2:$G$1093,MATCH($C15,'КАТАЛОГ'!$A$2:$A$1093,0)),"") | J15: Standard | L15: =IF($C15="","",IFERROR(INDEX('03 НАВЫКИ'!$I$5:$I$76,MATCH($E15,'03 НАВЫКИ'!$C$5:$C$76,0))+IF($J15="Excellent",1,IF($J15="Poor",-1,0)),0))
B16: 8 | D16: =IFERROR(INDEX('КАТАЛОГ'!$C$2:$C$1093,MATCH($C16,'КАТАЛОГ'!$A$2:$A$1093,0)),"") | E16: =IFERROR(INDEX('КАТАЛОГ'!$D$2:$D$1093,MATCH($C16,'КАТАЛОГ'!$A$2:$A$1093,0)),"") | F16: =IFERROR(INDEX('КАТАЛОГ'!$E$2:$E$1093,MATCH($C16,'КАТАЛОГ'!$A$2:$A$1093,0)),"") | G16: =IFERROR(INDEX('КАТАЛОГ'!$F$2:$F$1093,MATCH($C16,'КАТАЛОГ'!$A$2:$A$1093,0)),"") | H16: =IFERROR(INDEX('КАТАЛОГ'!$G$2:$G$1093,MATCH($C16,'КАТАЛОГ'!$A$2:$A$1093,0)),"") | J16: Standard | L16: =IF($C16="","",IFERROR(INDEX('03 НАВЫКИ'!$I$5:$I$76,MATCH($E16,'03 НАВЫКИ'!$C$5:$C$76,0))+IF($J16="Excellent",1,IF($J16="Poor",-1,0)),0))
B17: Атака = 1d10 + «БАЗА АТАКИ» (это уровень навыка + стата с учётом штрафа брони). Патроны пиши прямо тут: «AP ×24», «Basic ×30».
B18: УЧЁТ ДЕНЕГ: траты считаются из блока Ⅲ «ИНВЕНТАРЬ» — оружие, патроны и снаряжение впиши и сюда (для игры), и туда (для бюджета). Броня считается из блока Ⅱ (цена в колонке N, в бюджет — O), хром — с листа 04. Броню и хром в инвентарь дублировать НЕ надо: иначе они посчитаются дважды.
B19: Ⅱ · БРОНЯ И ЩИТ · В ЛОКАЦИИ РАБОТАЕТ ТОЛЬКО ЛУЧШИЙ SP, ШТРАФ БЕРЁТСЯ ОДИН РАЗ · ЦЕНА И УЧЁТ В БЮДЖЕТЕ — КОЛОНКИ N И O
B20: № | C20: НАЗВАНИЕ | D20: ЛОКАЦИЯ | E20: НАДЕТО | F20: SP | G20: HP (ЩИТ) | H20: ШТРАФ REF | I20: ШТРАФ DEX | J20: ШТРАФ MOVE | K20: SP СЕЙЧАС | L20: ЭФФ. SP | M20: ЗАМЕТКИ | N20: ЦЕНА €$ | O20: В БЮДЖЕТ €$
B21: 1 | C21: Light Armorjack | D21: Тело | E21: Да | F21: =IFERROR(INDEX('КАТАЛОГ'!$H$2:$H$1093,MATCH($C21,'КАТАЛОГ'!$A$2:$A$1093,0)),0) | G21: =IFERROR(INDEX('КАТАЛОГ'!$I$2:$I$1093,MATCH($C21,'КАТАЛОГ'!$A$2:$A$1093,0)),0) | H21: =IFERROR(INDEX('КАТАЛОГ'!$J$2:$J$1093,MATCH($C21,'КАТАЛОГ'!$A$2:$A$1093,0)),0) | I21: =IFERROR(INDEX('КАТАЛОГ'!$K$2:$K$1093,MATCH($C21,'КАТАЛОГ'!$A$2:$A$1093,0)),0) | J21: =IFERROR(INDEX('КАТАЛОГ'!$L$2:$L$1093,MATCH($C21,'КАТАЛОГ'!$A$2:$A$1093,0)),0) | L21: =IF($E21<>"Да",0,IF($K21<>"",$K21,$F21)) | M21: SP 11, штрафа нет — уклонение работает | N21: =IF($C21="",0,IFERROR(INDEX('КАТАЛОГ'!$R$2:$R$1093,MATCH($C21,'КАТАЛОГ'!$A$2:$A$1093,0)),0)) | O21: =IF($C21="",0,IF(COUNTIF($C$34:$C$53,$C21)>0,0,$N21))
B22: 2 | C22: Light Armorjack | D22: Голова | E22: Да | F22: =IFERROR(INDEX('КАТАЛОГ'!$H$2:$H$1093,MATCH($C22,'КАТАЛОГ'!$A$2:$A$1093,0)),0) | G22: =IFERROR(INDEX('КАТАЛОГ'!$I$2:$I$1093,MATCH($C22,'КАТАЛОГ'!$A$2:$A$1093,0)),0) | H22: =IFERROR(INDEX('КАТАЛОГ'!$J$2:$J$1093,MATCH($C22,'КАТАЛОГ'!$A$2:$A$1093,0)),0) | I22: =IFERROR(INDEX('КАТАЛОГ'!$K$2:$K$1093,MATCH($C22,'КАТАЛОГ'!$A$2:$A$1093,0)),0) | J22: =IFERROR(INDEX('КАТАЛОГ'!$L$2:$L$1093,MATCH($C22,'КАТАЛОГ'!$A$2:$A$1093,0)),0) | L22: =IF($E22<>"Да",0,IF($K22<>"",$K22,$F22)) | M22: Покупается отдельно на голову | N22: =IF($C22="",0,IFERROR(INDEX('КАТАЛОГ'!$R$2:$R$1093,MATCH($C22,'КАТАЛОГ'!$A$2:$A$1093,0)),0)) | O22: =IF($C22="",0,IF(COUNTIF($C$34:$C$53,$C22)>0,0,$N22))
B23: 3 | C23: Bulletproof Shield | D23: Щит | E23: Да | F23: =IFERROR(INDEX('КАТАЛОГ'!$H$2:$H$1093,MATCH($C23,'КАТАЛОГ'!$A$2:$A$1093,0)),0) | G23: =IFERROR(INDEX('КАТАЛОГ'!$I$2:$I$1093,MATCH($C23,'КАТАЛОГ'!$A$2:$A$1093,0)),0) | H23: =IFERROR(INDEX('КАТАЛОГ'!$J$2:$J$1093,MATCH($C23,'КАТАЛОГ'!$A$2:$A$1093,0)),0) | I23: =IFERROR(INDEX('КАТАЛОГ'!$K$2:$K$1093,MATCH($C23,'КАТАЛОГ'!$A$2:$A$1093,0)),0) | J23: =IFERROR(INDEX('КАТАЛОГ'!$L$2:$L$1093,MATCH($C23,'КАТАЛОГ'!$A$2:$A$1093,0)),0) | L23: =IF($E23<>"Да",0,IF($K23<>"",$K23,$F23)) | M23: Подвижное укрытие: принимает весь урон в свои HP | N23: =IF($C23="",0,IFERROR(INDEX('КАТАЛОГ'!$R$2:$R$1093,MATCH($C23,'КАТАЛОГ'!$A$2:$A$1093,0)),0)) | O23: =IF($C23="",0,IF(COUNTIF($C$34:$C$53,$C23)>0,0,$N23))
B24: 4 | D24: Тело | E24: Нет | F24: =IFERROR(INDEX('КАТАЛОГ'!$H$2:$H$1093,MATCH($C24,'КАТАЛОГ'!$A$2:$A$1093,0)),0) | G24: =IFERROR(INDEX('КАТАЛОГ'!$I$2:$I$1093,MATCH($C24,'КАТАЛОГ'!$A$2:$A$1093,0)),0) | H24: =IFERROR(INDEX('КАТАЛОГ'!$J$2:$J$1093,MATCH($C24,'КАТАЛОГ'!$A$2:$A$1093,0)),0) | I24: =IFERROR(INDEX('КАТАЛОГ'!$K$2:$K$1093,MATCH($C24,'КАТАЛОГ'!$A$2:$A$1093,0)),0) | J24: =IFERROR(INDEX('КАТАЛОГ'!$L$2:$L$1093,MATCH($C24,'КАТАЛОГ'!$A$2:$A$1093,0)),0) | L24: =IF($E24<>"Да",0,IF($K24<>"",$K24,$F24)) | N24: =IF($C24="",0,IFERROR(INDEX('КАТАЛОГ'!$R$2:$R$1093,MATCH($C24,'КАТАЛОГ'!$A$2:$A$1093,0)),0)) | O24: =IF($C24="",0,IF(COUNTIF($C$34:$C$53,$C24)>0,0,$N24))
B25: 5 | D25: Тело | E25: Нет | F25: =IFERROR(INDEX('КАТАЛОГ'!$H$2:$H$1093,MATCH($C25,'КАТАЛОГ'!$A$2:$A$1093,0)),0) | G25: =IFERROR(INDEX('КАТАЛОГ'!$I$2:$I$1093,MATCH($C25,'КАТАЛОГ'!$A$2:$A$1093,0)),0) | H25: =IFERROR(INDEX('КАТАЛОГ'!$J$2:$J$1093,MATCH($C25,'КАТАЛОГ'!$A$2:$A$1093,0)),0) | I25: =IFERROR(INDEX('КАТАЛОГ'!$K$2:$K$1093,MATCH($C25,'КАТАЛОГ'!$A$2:$A$1093,0)),0) | J25: =IFERROR(INDEX('КАТАЛОГ'!$L$2:$L$1093,MATCH($C25,'КАТАЛОГ'!$A$2:$A$1093,0)),0) | L25: =IF($E25<>"Да",0,IF($K25<>"",$K25,$F25)) | N25: =IF($C25="",0,IFERROR(INDEX('КАТАЛОГ'!$R$2:$R$1093,MATCH($C25,'КАТАЛОГ'!$A$2:$A$1093,0)),0)) | O25: =IF($C25="",0,IF(COUNTIF($C$34:$C$53,$C25)>0,0,$N25))
B26: 6 | D26: Тело | E26: Нет | F26: =IFERROR(INDEX('КАТАЛОГ'!$H$2:$H$1093,MATCH($C26,'КАТАЛОГ'!$A$2:$A$1093,0)),0) | G26: =IFERROR(INDEX('КАТАЛОГ'!$I$2:$I$1093,MATCH($C26,'КАТАЛОГ'!$A$2:$A$1093,0)),0) | H26: =IFERROR(INDEX('КАТАЛОГ'!$J$2:$J$1093,MATCH($C26,'КАТАЛОГ'!$A$2:$A$1093,0)),0) | I26: =IFERROR(INDEX('КАТАЛОГ'!$K$2:$K$1093,MATCH($C26,'КАТАЛОГ'!$A$2:$A$1093,0)),0) | J26: =IFERROR(INDEX('КАТАЛОГ'!$L$2:$L$1093,MATCH($C26,'КАТАЛОГ'!$A$2:$A$1093,0)),0) | L26: =IF($E26<>"Да",0,IF($K26<>"",$K26,$F26)) | N26: =IF($C26="",0,IFERROR(INDEX('КАТАЛОГ'!$R$2:$R$1093,MATCH($C26,'КАТАЛОГ'!$A$2:$A$1093,0)),0)) | O26: =IF($C26="",0,IF(COUNTIF($C$34:$C$53,$C26)>0,0,$N26))
B27: SP ГОЛОВЫ (НАДЕТОЕ) | D27: =SUMPRODUCT(MAX(($D$21:$D$26="Голова")*($E$21:$E$26="Да")*$L$21:$L$26)) | E27: Работает лучший SP в локации — второй слой не складывается.
B28: SP ТЕЛА (НАДЕТОЕ) | D28: =SUMPRODUCT(MAX(($D$21:$D$26="Тело")*($E$21:$E$26="Да")*$L$21:$L$26)) | E28: Вся надетая броня локации аблейтится одновременно (−1 за каждое попадание).
B29: ЩИТ: HP | D29: =SUMPRODUCT(MAX(($D$21:$D$26="Щит")*($E$21:$E$26="Да")*$G$21:$G$26)) | E29: Обычный щит 10 HP, усиленный 15 HP. Взять/бросить — Действие.
B30: ШТРАФ БРОНИ REF / DEX / MOVE (ПОЛОЖИТЕЛЬНЫЙ) | D30: =-SUMPRODUCT(MIN(($E$21:$E$26="Да")*$H$21:$H$26)) | E30: =-SUMPRODUCT(MIN(($E$21:$E$26="Да")*$I$21:$I$26)) | F30: =-SUMPRODUCT(MIN(($E$21:$E$26="Да")*$J$21:$J$26)) | G30: Самый строгий штраф из надетого, применяется один раз — он уже вычтен из REF/DEX/MOVE на листе 02. Хочешь ослабить броню — снимай вещи, а не правь эти цифры.
B32: Ⅲ · ИНВЕНТАРЬ · СУММЫ ОТСЮДА ИДУТ В ОБА БЮДЖЕТА ВМЕСТЕ С БРОНЁЙ (Ⅱ) И ХРОМОМ (ЛИСТ 04)
B33: № | C33: НАЗВАНИЕ | D33: КАТЕГОРИЯ | E33: ПОДТИП | F33: КОЛ-ВО | G33: ЦЕНА €$ | H33: ЦЕНА СВОЯ | I33: СУММА | J33: ГДЕ НОСИТ | K33: ЗАМЕТКА | M33: ОПИСАНИЕ ИЗ КАТАЛОГА
B34: 1 | C34: Con Arms Unity | D34: =IFERROR(INDEX('КАТАЛОГ'!$B$2:$B$1093,MATCH($C34,'КАТАЛОГ'!$A$2:$A$1093,0)),"") | E34: =IFERROR(INDEX('КАТАЛОГ'!$C$2:$C$1093,MATCH($C34,'КАТАЛОГ'!$A$2:$A$1093,0)),"") | G34: =IFERROR(INDEX('КАТАЛОГ'!$R$2:$R$1093,MATCH($C34,'КАТАЛОГ'!$A$2:$A$1093,0)),"") | I34: =IF($C34="",0,IF($H34<>"",$H34,IF(ISNUMBER($G34),$G34,0))*IF($F34="",1,$F34)) | J34: в кобуре | M34: =IFERROR(LEFT(INDEX('КАТАЛОГ'!$T$2:$T$1093,MATCH($C34,'КАТАЛОГ'!$A$2:$A$1093,0)),90),"")
B35: 2 | C35: Rostović DB-2 Satara | D35: =IFERROR(INDEX('КАТАЛОГ'!$B$2:$B$1093,MATCH($C35,'КАТАЛОГ'!$A$2:$A$1093,0)),"") | E35: =IFERROR(INDEX('КАТАЛОГ'!$C$2:$C$1093,MATCH($C35,'КАТАЛОГ'!$A$2:$A$1093,0)),"") | G35: =IFERROR(INDEX('КАТАЛОГ'!$R$2:$R$1093,MATCH($C35,'КАТАЛОГ'!$A$2:$A$1093,0)),"") | I35: =IF($C35="",0,IF($H35<>"",$H35,IF(ISNUMBER($G35),$G35,0))*IF($F35="",1,$F35)) | J35: за спиной / в машине | M35: =IFERROR(LEFT(INDEX('КАТАЛОГ'!$T$2:$T$1093,MATCH($C35,'КАТАЛОГ'!$A$2:$A$1093,0)),90),"")
B36: 3 | C36: Handcuffs | D36: =IFERROR(INDEX('КАТАЛОГ'!$B$2:$B$1093,MATCH($C36,'КАТАЛОГ'!$A$2:$A$1093,0)),"") | E36: =IFERROR(INDEX('КАТАЛОГ'!$C$2:$C$1093,MATCH($C36,'КАТАЛОГ'!$A$2:$A$1093,0)),"") | G36: =IFERROR(INDEX('КАТАЛОГ'!$R$2:$R$1093,MATCH($C36,'КАТАЛОГ'!$A$2:$A$1093,0)),"") | I36: =IF($C36="",0,IF($H36<>"",$H36,IF(ISNUMBER($G36),$G36,0))*IF($F36="",1,$F36)) | J36: на поясе | M36: =IFERROR(LEFT(INDEX('КАТАЛОГ'!$T$2:$T$1093,MATCH($C36,'КАТАЛОГ'!$A$2:$A$1093,0)),90),"")
B37: 4 | C37: Basic | D37: =IFERROR(INDEX('КАТАЛОГ'!$B$2:$B$1093,MATCH($C37,'КАТАЛОГ'!$A$2:$A$1093,0)),"") | E37: =IFERROR(INDEX('КАТАЛОГ'!$C$2:$C$1093,MATCH($C37,'КАТАЛОГ'!$A$2:$A$1093,0)),"") | F37: 6 | G37: =IFERROR(INDEX('КАТАЛОГ'!$R$2:$R$1093,MATCH($C37,'КАТАЛОГ'!$A$2:$A$1093,0)),"") | I37: =IF($C37="",0,IF($H37<>"",$H37,IF(ISNUMBER($G37),$G37,0))*IF($F37="",1,$F37)) | J37: подсумок | K37: 40 пистолетных + 20 картечи | M37: =IFERROR(LEFT(INDEX('КАТАЛОГ'!$T$2:$T$1093,MATCH($C37,'КАТАЛОГ'!$A$2:$A$1093,0)),90),"")
B38: 5 | C38: Agent (Standard) | D38: =IFERROR(INDEX('КАТАЛОГ'!$B$2:$B$1093,MATCH($C38,'КАТАЛОГ'!$A$2:$A$1093,0)),"") | E38: =IFERROR(INDEX('КАТАЛОГ'!$C$2:$C$1093,MATCH($C38,'КАТАЛОГ'!$A$2:$A$1093,0)),"") | G38: =IFERROR(INDEX('КАТАЛОГ'!$R$2:$R$1093,MATCH($C38,'КАТАЛОГ'!$A$2:$A$1093,0)),"") | I38: =IF($C38="",0,IF($H38<>"",$H38,IF(ISNUMBER($G38),$G38,0))*IF($F38="",1,$F38)) | J38: карман | M38: =IFERROR(LEFT(INDEX('КАТАЛОГ'!$T$2:$T$1093,MATCH($C38,'КАТАЛОГ'!$A$2:$A$1093,0)),90),"")
